[2023-06-21 14:23:02 +0700] [23547] [INFO] Starting gunicorn 20.1.0
[2023-06-21 14:23:02 +0700] [23547] [INFO] Listening at: unix:/run/devc.sock (23547)
[2023-06-21 14:23:02 +0700] [23547] [INFO] Using worker: sync
[2023-06-21 14:23:02 +0700] [23548] [INFO] Booting worker with pid: 23548
[2023-06-21 14:23:06,426] ERROR in app: Exception on /players [GET]
Traceback (most recent call last):
  File "/usr/lib/python3/dist-packages/flask/app.py", line 2070, in wsgi_app
    response = self.full_dispatch_request()
  File "/usr/lib/python3/dist-packages/flask/app.py", line 1515, in full_dispatch_request
    rv = self.handle_user_exception(e)
  File "/usr/lib/python3/dist-packages/flask/app.py", line 1513, in full_dispatch_request
    rv = self.dispatch_request()
  File "/usr/lib/python3/dist-packages/flask/app.py", line 1499, in dispatch_request
    return self.ensure_sync(self.view_functions[rule.endpoint])(**req.view_args)
  File "/home/ultiv/Code/DevC/app.py", line 29, in get_players
    player["rank"] = ranks[player["rank"]]
IndexError: list index out of range
[2023-06-21 14:23:27 +0700] [23548] [INFO] Worker reloading: /home/ultiv/Code/DevC/app.py modified
[2023-06-21 14:23:27 +0700] [23548] [INFO] Worker exiting (pid: 23548)
[2023-06-21 14:23:27 +0700] [23567] [INFO] Booting worker with pid: 23567
[2023-06-21 14:24:16 +0700] [23567] [INFO] Worker reloading: /home/ultiv/Code/DevC/app.py modified
[2023-06-21 14:24:16 +0700] [23567] [INFO] Worker exiting (pid: 23567)
[2023-06-21 14:24:16 +0700] [23585] [INFO] Booting worker with pid: 23585
[2023-06-21 14:24:17,931] ERROR in app: Exception on /players [GET]
Traceback (most recent call last):
  File "/usr/lib/python3/dist-packages/flask/app.py", line 2070, in wsgi_app
    response = self.full_dispatch_request()
  File "/usr/lib/python3/dist-packages/flask/app.py", line 1515, in full_dispatch_request
    rv = self.handle_user_exception(e)
  File "/usr/lib/python3/dist-packages/flask/app.py", line 1513, in full_dispatch_request
    rv = self.dispatch_request()
  File "/usr/lib/python3/dist-packages/flask/app.py", line 1499, in dispatch_request
    return self.ensure_sync(self.view_functions[rule.endpoint])(**req.view_args)
  File "/home/ultiv/Code/DevC/app.py", line 31, in get_players
    player["pos2"] = positions[player["pos2"]]
IndexError: list index out of range
[2023-06-21 14:26:10,351] ERROR in app: Exception on /players [GET]
Traceback (most recent call last):
  File "/usr/lib/python3/dist-packages/flask/app.py", line 2070, in wsgi_app
    response = self.full_dispatch_request()
  File "/usr/lib/python3/dist-packages/flask/app.py", line 1515, in full_dispatch_request
    rv = self.handle_user_exception(e)
  File "/usr/lib/python3/dist-packages/flask/app.py", line 1513, in full_dispatch_request
    rv = self.dispatch_request()
  File "/usr/lib/python3/dist-packages/flask/app.py", line 1499, in dispatch_request
    return self.ensure_sync(self.view_functions[rule.endpoint])(**req.view_args)
  File "/home/ultiv/Code/DevC/app.py", line 31, in get_players
    player["pos2"] = positions[player["pos2"]]
TypeError: list indices must be integers or slices, not str
[2023-06-21 14:26:59 +0700] [23585] [INFO] Worker reloading: /home/ultiv/Code/DevC/app.py modified
[2023-06-21 14:26:59 +0700] [23585] [INFO] Worker exiting (pid: 23585)
[2023-06-21 14:27:00 +0700] [23855] [INFO] Booting worker with pid: 23855
[2023-06-21 15:02:30 +0700] [23547] [INFO] Handling signal: term
[2023-06-21 15:02:30 +0700] [23855] [INFO] Worker exiting (pid: 23855)
[2023-06-21 15:02:31 +0700] [23547] [INFO] Shutting down: Master
[2023-06-22 15:54:32 +0700] [11569] [INFO] Starting gunicorn 20.1.0
[2023-06-22 15:54:32 +0700] [11569] [INFO] Listening at: unix:/run/devc.sock (11569)
[2023-06-22 15:54:32 +0700] [11569] [INFO] Using worker: sync
[2023-06-22 15:54:32 +0700] [11570] [INFO] Booting worker with pid: 11570
[2023-06-22 15:54:32 +0700] [11570] [ERROR] Error handling request
Traceback (most recent call last):
  File "/usr/lib/python3/dist-packages/gunicorn/workers/sync.py", line 182, in handle_request
    resp.write_file(respiter)
  File "/usr/lib/python3/dist-packages/gunicorn/http/wsgi.py", line 385, in write_file
    if not self.sendfile(respiter):
  File "/usr/lib/python3/dist-packages/gunicorn/http/wsgi.py", line 375, in sendfile
    self.sock.sendfile(respiter.filelike, count=nbytes)
  File "/usr/lib/python3.10/socket.py", line 484, in sendfile
    return self._sendfile_use_sendfile(file, offset, count)
  File "/usr/lib/python3.10/socket.py", line 348, in _sendfile_use_sendfile
    self._check_sendfile_params(file, offset, count)
  File "/usr/lib/python3.10/socket.py", line 462, in _check_sendfile_params
    raise ValueError(
ValueError: count must be a positive integer (got 0)
[2023-06-22 15:59:29 +0700] [11570] [ERROR] Error handling request
Traceback (most recent call last):
  File "/usr/lib/python3/dist-packages/gunicorn/workers/sync.py", line 182, in handle_request
    resp.write_file(respiter)
  File "/usr/lib/python3/dist-packages/gunicorn/http/wsgi.py", line 385, in write_file
    if not self.sendfile(respiter):
  File "/usr/lib/python3/dist-packages/gunicorn/http/wsgi.py", line 375, in sendfile
    self.sock.sendfile(respiter.filelike, count=nbytes)
  File "/usr/lib/python3.10/socket.py", line 484, in sendfile
    return self._sendfile_use_sendfile(file, offset, count)
  File "/usr/lib/python3.10/socket.py", line 348, in _sendfile_use_sendfile
    self._check_sendfile_params(file, offset, count)
  File "/usr/lib/python3.10/socket.py", line 462, in _check_sendfile_params
    raise ValueError(
ValueError: count must be a positive integer (got 0)
[2023-06-22 16:03:18 +0700] [11570] [INFO] Worker reloading: /home/ultiv/Code/DevC/app.py modified
[2023-06-22 16:03:18 +0700] [11570] [INFO] Worker exiting (pid: 11570)
[2023-06-22 16:03:18 +0700] [12507] [INFO] Booting worker with pid: 12507
[2023-06-22 16:03:18 +0700] [12507] [ERROR] Exception in worker process
Traceback (most recent call last):
  File "/usr/lib/python3/dist-packages/gunicorn/arbiter.py", line 589, in spawn_worker
    worker.init_process()
  File "/usr/lib/python3/dist-packages/gunicorn/workers/base.py", line 134, in init_process
    self.load_wsgi()
  File "/usr/lib/python3/dist-packages/gunicorn/workers/base.py", line 146, in load_wsgi
    self.wsgi = self.app.wsgi()
  File "/usr/lib/python3/dist-packages/gunicorn/app/base.py", line 67, in wsgi
    self.callable = self.load()
  File "/usr/lib/python3/dist-packages/gunicorn/app/wsgiapp.py", line 58, in load
    return self.load_wsgiapp()
  File "/usr/lib/python3/dist-packages/gunicorn/app/wsgiapp.py", line 48, in load_wsgiapp
    return util.import_app(self.app_uri)
  File "/usr/lib/python3/dist-packages/gunicorn/util.py", line 384, in import_app
    mod = importlib.import_module(module)
  File "/usr/lib/python3.10/importlib/__init__.py", line 126, in import_module
    return _bootstrap._gcd_import(name[level:], package, level)
  File "<frozen importlib._bootstrap>", line 1050, in _gcd_import
  File "<frozen importlib._bootstrap>", line 1027, in _find_and_load
  File "<frozen importlib._bootstrap>", line 1006, in _find_and_load_unlocked
  File "<frozen importlib._bootstrap>", line 688, in _load_unlocked
  File "<frozen importlib._bootstrap_external>", line 883, in exec_module
  File "<frozen importlib._bootstrap>", line 241, in _call_with_frames_removed
  File "/home/ultiv/Code/DevC/app.py", line 50, in <module>
    def balance():
  File "/usr/lib/python3/dist-packages/flask/scaffold.py", line 435, in decorator
    self.add_url_rule(rule, endpoint, f, **options)
  File "/usr/lib/python3/dist-packages/flask/scaffold.py", line 56, in wrapper_func
    return f(self, *args, **kwargs)
  File "/usr/lib/python3/dist-packages/flask/app.py", line 1085, in add_url_rule
    rule = self.url_rule_class(rule, methods=methods, **options)
  File "/usr/lib/python3/dist-packages/werkzeug/routing.py", line 697, in __init__
    raise ValueError("urls must start with a leading slash")
ValueError: urls must start with a leading slash
[2023-06-22 16:03:18 +0700] [12507] [INFO] Worker exiting (pid: 12507)
[2023-06-22 16:03:19 +0700] [11569] [INFO] Shutting down: Master
[2023-06-22 16:03:19 +0700] [11569] [INFO] Reason: Worker failed to boot.
[2023-06-22 16:14:54 +0700] [13063] [INFO] Starting gunicorn 20.1.0
[2023-06-22 16:14:54 +0700] [13063] [INFO] Listening at: unix:/run/devc.sock (13063)
[2023-06-22 16:14:54 +0700] [13063] [INFO] Using worker: sync
[2023-06-22 16:14:54 +0700] [13064] [INFO] Booting worker with pid: 13064
[2023-06-22 16:14:54 +0700] [13064] [ERROR] Exception in worker process
Traceback (most recent call last):
  File "/usr/lib/python3/dist-packages/gunicorn/arbiter.py", line 589, in spawn_worker
    worker.init_process()
  File "/usr/lib/python3/dist-packages/gunicorn/workers/base.py", line 134, in init_process
    self.load_wsgi()
  File "/usr/lib/python3/dist-packages/gunicorn/workers/base.py", line 146, in load_wsgi
    self.wsgi = self.app.wsgi()
  File "/usr/lib/python3/dist-packages/gunicorn/app/base.py", line 67, in wsgi
    self.callable = self.load()
  File "/usr/lib/python3/dist-packages/gunicorn/app/wsgiapp.py", line 58, in load
    return self.load_wsgiapp()
  File "/usr/lib/python3/dist-packages/gunicorn/app/wsgiapp.py", line 48, in load_wsgiapp
    return util.import_app(self.app_uri)
  File "/usr/lib/python3/dist-packages/gunicorn/util.py", line 384, in import_app
    mod = importlib.import_module(module)
  File "/usr/lib/python3.10/importlib/__init__.py", line 126, in import_module
    return _bootstrap._gcd_import(name[level:], package, level)
  File "<frozen importlib._bootstrap>", line 1050, in _gcd_import
  File "<frozen importlib._bootstrap>", line 1027, in _find_and_load
  File "<frozen importlib._bootstrap>", line 1006, in _find_and_load_unlocked
  File "<frozen importlib._bootstrap>", line 688, in _load_unlocked
  File "<frozen importlib._bootstrap_external>", line 883, in exec_module
  File "<frozen importlib._bootstrap>", line 241, in _call_with_frames_removed
  File "/home/ultiv/Code/DevC/app.py", line 52, in <module>
    def balance():
  File "/usr/lib/python3/dist-packages/flask/scaffold.py", line 435, in decorator
    self.add_url_rule(rule, endpoint, f, **options)
  File "/usr/lib/python3/dist-packages/flask/scaffold.py", line 56, in wrapper_func
    return f(self, *args, **kwargs)
  File "/usr/lib/python3/dist-packages/flask/app.py", line 1085, in add_url_rule
    rule = self.url_rule_class(rule, methods=methods, **options)
  File "/usr/lib/python3/dist-packages/werkzeug/routing.py", line 697, in __init__
    raise ValueError("urls must start with a leading slash")
ValueError: urls must start with a leading slash
[2023-06-22 16:14:54 +0700] [13064] [INFO] Worker exiting (pid: 13064)
[2023-06-22 16:14:54 +0700] [13063] [INFO] Shutting down: Master
[2023-06-22 16:14:54 +0700] [13063] [INFO] Reason: Worker failed to boot.
[2023-06-22 16:14:54 +0700] [13073] [INFO] Starting gunicorn 20.1.0
[2023-06-22 16:14:54 +0700] [13073] [INFO] Listening at: unix:/run/devc.sock (13073)
[2023-06-22 16:14:54 +0700] [13073] [INFO] Using worker: sync
[2023-06-22 16:14:54 +0700] [13074] [INFO] Booting worker with pid: 13074
[2023-06-22 16:14:54 +0700] [13074] [ERROR] Exception in worker process
Traceback (most recent call last):
  File "/usr/lib/python3/dist-packages/gunicorn/arbiter.py", line 589, in spawn_worker
    worker.init_process()
  File "/usr/lib/python3/dist-packages/gunicorn/workers/base.py", line 134, in init_process
    self.load_wsgi()
  File "/usr/lib/python3/dist-packages/gunicorn/workers/base.py", line 146, in load_wsgi
    self.wsgi = self.app.wsgi()
  File "/usr/lib/python3/dist-packages/gunicorn/app/base.py", line 67, in wsgi
    self.callable = self.load()
  File "/usr/lib/python3/dist-packages/gunicorn/app/wsgiapp.py", line 58, in load
    return self.load_wsgiapp()
  File "/usr/lib/python3/dist-packages/gunicorn/app/wsgiapp.py", line 48, in load_wsgiapp
    return util.import_app(self.app_uri)
  File "/usr/lib/python3/dist-packages/gunicorn/util.py", line 384, in import_app
    mod = importlib.import_module(module)
  File "/usr/lib/python3.10/importlib/__init__.py", line 126, in import_module
    return _bootstrap._gcd_import(name[level:], package, level)
  File "<frozen importlib._bootstrap>", line 1050, in _gcd_import
  File "<frozen importlib._bootstrap>", line 1027, in _find_and_load
  File "<frozen importlib._bootstrap>", line 1006, in _find_and_load_unlocked
  File "<frozen importlib._bootstrap>", line 688, in _load_unlocked
  File "<frozen importlib._bootstrap_external>", line 883, in exec_module
  File "<frozen importlib._bootstrap>", line 241, in _call_with_frames_removed
  File "/home/ultiv/Code/DevC/app.py", line 52, in <module>
    def balance():
  File "/usr/lib/python3/dist-packages/flask/scaffold.py", line 435, in decorator
    self.add_url_rule(rule, endpoint, f, **options)
  File "/usr/lib/python3/dist-packages/flask/scaffold.py", line 56, in wrapper_func
    return f(self, *args, **kwargs)
  File "/usr/lib/python3/dist-packages/flask/app.py", line 1085, in add_url_rule
    rule = self.url_rule_class(rule, methods=methods, **options)
  File "/usr/lib/python3/dist-packages/werkzeug/routing.py", line 697, in __init__
    raise ValueError("urls must start with a leading slash")
ValueError: urls must start with a leading slash
[2023-06-22 16:14:54 +0700] [13074] [INFO] Worker exiting (pid: 13074)
[2023-06-22 16:14:55 +0700] [13073] [INFO] Shutting down: Master
[2023-06-22 16:14:55 +0700] [13073] [INFO] Reason: Worker failed to boot.
[2023-06-22 16:14:55 +0700] [13082] [INFO] Starting gunicorn 20.1.0
[2023-06-22 16:14:55 +0700] [13082] [INFO] Listening at: unix:/run/devc.sock (13082)
[2023-06-22 16:14:55 +0700] [13082] [INFO] Using worker: sync
[2023-06-22 16:14:55 +0700] [13083] [INFO] Booting worker with pid: 13083
[2023-06-22 16:14:55 +0700] [13083] [ERROR] Exception in worker process
Traceback (most recent call last):
  File "/usr/lib/python3/dist-packages/gunicorn/arbiter.py", line 589, in spawn_worker
    worker.init_process()
  File "/usr/lib/python3/dist-packages/gunicorn/workers/base.py", line 134, in init_process
    self.load_wsgi()
  File "/usr/lib/python3/dist-packages/gunicorn/workers/base.py", line 146, in load_wsgi
    self.wsgi = self.app.wsgi()
  File "/usr/lib/python3/dist-packages/gunicorn/app/base.py", line 67, in wsgi
    self.callable = self.load()
  File "/usr/lib/python3/dist-packages/gunicorn/app/wsgiapp.py", line 58, in load
    return self.load_wsgiapp()
  File "/usr/lib/python3/dist-packages/gunicorn/app/wsgiapp.py", line 48, in load_wsgiapp
    return util.import_app(self.app_uri)
  File "/usr/lib/python3/dist-packages/gunicorn/util.py", line 384, in import_app
    mod = importlib.import_module(module)
  File "/usr/lib/python3.10/importlib/__init__.py", line 126, in import_module
    return _bootstrap._gcd_import(name[level:], package, level)
  File "<frozen importlib._bootstrap>", line 1050, in _gcd_import
  File "<frozen importlib._bootstrap>", line 1027, in _find_and_load
  File "<frozen importlib._bootstrap>", line 1006, in _find_and_load_unlocked
  File "<frozen importlib._bootstrap>", line 688, in _load_unlocked
  File "<frozen importlib._bootstrap_external>", line 883, in exec_module
  File "<frozen importlib._bootstrap>", line 241, in _call_with_frames_removed
  File "/home/ultiv/Code/DevC/app.py", line 52, in <module>
    def balance():
  File "/usr/lib/python3/dist-packages/flask/scaffold.py", line 435, in decorator
    self.add_url_rule(rule, endpoint, f, **options)
  File "/usr/lib/python3/dist-packages/flask/scaffold.py", line 56, in wrapper_func
    return f(self, *args, **kwargs)
  File "/usr/lib/python3/dist-packages/flask/app.py", line 1085, in add_url_rule
    rule = self.url_rule_class(rule, methods=methods, **options)
  File "/usr/lib/python3/dist-packages/werkzeug/routing.py", line 697, in __init__
    raise ValueError("urls must start with a leading slash")
ValueError: urls must start with a leading slash
[2023-06-22 16:14:55 +0700] [13083] [INFO] Worker exiting (pid: 13083)
[2023-06-22 16:14:56 +0700] [13082] [INFO] Shutting down: Master
[2023-06-22 16:14:56 +0700] [13082] [INFO] Reason: Worker failed to boot.
[2023-06-22 16:14:56 +0700] [13093] [INFO] Starting gunicorn 20.1.0
[2023-06-22 16:14:56 +0700] [13093] [INFO] Listening at: unix:/run/devc.sock (13093)
[2023-06-22 16:14:56 +0700] [13093] [INFO] Using worker: sync
[2023-06-22 16:14:56 +0700] [13094] [INFO] Booting worker with pid: 13094
[2023-06-22 16:14:56 +0700] [13094] [ERROR] Exception in worker process
Traceback (most recent call last):
  File "/usr/lib/python3/dist-packages/gunicorn/arbiter.py", line 589, in spawn_worker
    worker.init_process()
  File "/usr/lib/python3/dist-packages/gunicorn/workers/base.py", line 134, in init_process
    self.load_wsgi()
  File "/usr/lib/python3/dist-packages/gunicorn/workers/base.py", line 146, in load_wsgi
    self.wsgi = self.app.wsgi()
  File "/usr/lib/python3/dist-packages/gunicorn/app/base.py", line 67, in wsgi
    self.callable = self.load()
  File "/usr/lib/python3/dist-packages/gunicorn/app/wsgiapp.py", line 58, in load
    return self.load_wsgiapp()
  File "/usr/lib/python3/dist-packages/gunicorn/app/wsgiapp.py", line 48, in load_wsgiapp
    return util.import_app(self.app_uri)
  File "/usr/lib/python3/dist-packages/gunicorn/util.py", line 384, in import_app
    mod = importlib.import_module(module)
  File "/usr/lib/python3.10/importlib/__init__.py", line 126, in import_module
    return _bootstrap._gcd_import(name[level:], package, level)
  File "<frozen importlib._bootstrap>", line 1050, in _gcd_import
  File "<frozen importlib._bootstrap>", line 1027, in _find_and_load
  File "<frozen importlib._bootstrap>", line 1006, in _find_and_load_unlocked
  File "<frozen importlib._bootstrap>", line 688, in _load_unlocked
  File "<frozen importlib._bootstrap_external>", line 883, in exec_module
  File "<frozen importlib._bootstrap>", line 241, in _call_with_frames_removed
  File "/home/ultiv/Code/DevC/app.py", line 52, in <module>
    def balance():
  File "/usr/lib/python3/dist-packages/flask/scaffold.py", line 435, in decorator
    self.add_url_rule(rule, endpoint, f, **options)
  File "/usr/lib/python3/dist-packages/flask/scaffold.py", line 56, in wrapper_func
    return f(self, *args, **kwargs)
  File "/usr/lib/python3/dist-packages/flask/app.py", line 1085, in add_url_rule
    rule = self.url_rule_class(rule, methods=methods, **options)
  File "/usr/lib/python3/dist-packages/werkzeug/routing.py", line 697, in __init__
    raise ValueError("urls must start with a leading slash")
ValueError: urls must start with a leading slash
[2023-06-22 16:14:56 +0700] [13094] [INFO] Worker exiting (pid: 13094)
[2023-06-22 16:14:57 +0700] [13093] [INFO] Shutting down: Master
[2023-06-22 16:14:57 +0700] [13093] [INFO] Reason: Worker failed to boot.
[2023-06-22 16:14:57 +0700] [13102] [INFO] Starting gunicorn 20.1.0
[2023-06-22 16:14:57 +0700] [13102] [INFO] Listening at: unix:/run/devc.sock (13102)
[2023-06-22 16:14:57 +0700] [13102] [INFO] Using worker: sync
[2023-06-22 16:14:57 +0700] [13104] [INFO] Booting worker with pid: 13104
[2023-06-22 16:14:57 +0700] [13104] [ERROR] Exception in worker process
Traceback (most recent call last):
  File "/usr/lib/python3/dist-packages/gunicorn/arbiter.py", line 589, in spawn_worker
    worker.init_process()
  File "/usr/lib/python3/dist-packages/gunicorn/workers/base.py", line 134, in init_process
    self.load_wsgi()
  File "/usr/lib/python3/dist-packages/gunicorn/workers/base.py", line 146, in load_wsgi
    self.wsgi = self.app.wsgi()
  File "/usr/lib/python3/dist-packages/gunicorn/app/base.py", line 67, in wsgi
    self.callable = self.load()
  File "/usr/lib/python3/dist-packages/gunicorn/app/wsgiapp.py", line 58, in load
    return self.load_wsgiapp()
  File "/usr/lib/python3/dist-packages/gunicorn/app/wsgiapp.py", line 48, in load_wsgiapp
    return util.import_app(self.app_uri)
  File "/usr/lib/python3/dist-packages/gunicorn/util.py", line 384, in import_app
    mod = importlib.import_module(module)
  File "/usr/lib/python3.10/importlib/__init__.py", line 126, in import_module
    return _bootstrap._gcd_import(name[level:], package, level)
  File "<frozen importlib._bootstrap>", line 1050, in _gcd_import
  File "<frozen importlib._bootstrap>", line 1027, in _find_and_load
  File "<frozen importlib._bootstrap>", line 1006, in _find_and_load_unlocked
  File "<frozen importlib._bootstrap>", line 688, in _load_unlocked
  File "<frozen importlib._bootstrap_external>", line 883, in exec_module
  File "<frozen importlib._bootstrap>", line 241, in _call_with_frames_removed
  File "/home/ultiv/Code/DevC/app.py", line 52, in <module>
    def balance():
  File "/usr/lib/python3/dist-packages/flask/scaffold.py", line 435, in decorator
    self.add_url_rule(rule, endpoint, f, **options)
  File "/usr/lib/python3/dist-packages/flask/scaffold.py", line 56, in wrapper_func
    return f(self, *args, **kwargs)
  File "/usr/lib/python3/dist-packages/flask/app.py", line 1085, in add_url_rule
    rule = self.url_rule_class(rule, methods=methods, **options)
  File "/usr/lib/python3/dist-packages/werkzeug/routing.py", line 697, in __init__
    raise ValueError("urls must start with a leading slash")
ValueError: urls must start with a leading slash
[2023-06-22 16:14:57 +0700] [13104] [INFO] Worker exiting (pid: 13104)
[2023-06-22 16:14:57 +0700] [13102] [INFO] Shutting down: Master
[2023-06-22 16:14:57 +0700] [13102] [INFO] Reason: Worker failed to boot.
[2023-06-22 16:16:22 +0700] [13169] [INFO] Starting gunicorn 20.1.0
[2023-06-22 16:16:22 +0700] [13169] [INFO] Listening at: unix:/run/devc.sock (13169)
[2023-06-22 16:16:22 +0700] [13169] [INFO] Using worker: sync
[2023-06-22 16:16:22 +0700] [13170] [INFO] Booting worker with pid: 13170
[2023-06-22 16:16:28,656] ERROR in app: Exception on /teams [GET]
Traceback (most recent call last):
  File "/usr/lib/python3/dist-packages/flask/app.py", line 2070, in wsgi_app
    response = self.full_dispatch_request()
  File "/usr/lib/python3/dist-packages/flask/app.py", line 1515, in full_dispatch_request
    rv = self.handle_user_exception(e)
  File "/usr/lib/python3/dist-packages/flask/app.py", line 1513, in full_dispatch_request
    rv = self.dispatch_request()
  File "/usr/lib/python3/dist-packages/flask/app.py", line 1499, in dispatch_request
    return self.ensure_sync(self.view_functions[rule.endpoint])(**req.view_args)
  File "/home/ultiv/Code/DevC/app.py", line 53, in balance
    return render_template("teams.html", teams=balance())
  File "/home/ultiv/Code/DevC/app.py", line 53, in balance
    return render_template("teams.html", teams=balance())
  File "/home/ultiv/Code/DevC/app.py", line 53, in balance
    return render_template("teams.html", teams=balance())
  [Previous line repeated 978 more times]
RecursionError: maximum recursion depth exceeded
[2023-06-22 16:17:10 +0700] [13170] [INFO] Worker reloading: /home/ultiv/Code/DevC/balance.py modified
[2023-06-22 16:17:10 +0700] [13170] [INFO] Worker exiting (pid: 13170)
[2023-06-22 16:17:10 +0700] [13201] [INFO] Booting worker with pid: 13201
[2023-06-22 16:19:08,757] ERROR in app: Exception on /teams [GET]
Traceback (most recent call last):
  File "/usr/lib/python3/dist-packages/flask/app.py", line 2070, in wsgi_app
    response = self.full_dispatch_request()
  File "/usr/lib/python3/dist-packages/flask/app.py", line 1515, in full_dispatch_request
    rv = self.handle_user_exception(e)
  File "/usr/lib/python3/dist-packages/flask/app.py", line 1513, in full_dispatch_request
    rv = self.dispatch_request()
  File "/usr/lib/python3/dist-packages/flask/app.py", line 1499, in dispatch_request
    return self.ensure_sync(self.view_functions[rule.endpoint])(**req.view_args)
  File "/home/ultiv/Code/DevC/app.py", line 53, in balance
    return render_template("teams.html", teams=balance())
  File "/home/ultiv/Code/DevC/app.py", line 53, in balance
    return render_template("teams.html", teams=balance())
  File "/home/ultiv/Code/DevC/app.py", line 53, in balance
    return render_template("teams.html", teams=balance())
  [Previous line repeated 978 more times]
RecursionError: maximum recursion depth exceeded
[2023-06-22 16:19:38 +0700] [13201] [INFO] Worker reloading: /home/ultiv/Code/DevC/balance.py modified
[2023-06-22 16:19:38 +0700] [13201] [INFO] Worker exiting (pid: 13201)
[2023-06-22 16:19:39 +0700] [13382] [INFO] Booting worker with pid: 13382
[2023-06-22 16:24:22 +0700] [13382] [INFO] Worker reloading: /home/ultiv/Code/DevC/app.py modified
[2023-06-22 16:24:22 +0700] [13382] [INFO] Worker exiting (pid: 13382)
[2023-06-22 16:24:23 +0700] [13500] [INFO] Booting worker with pid: 13500
[2023-06-22 16:25:00,579] ERROR in app: Exception on /teams [GET]
Traceback (most recent call last):
  File "/usr/lib/python3/dist-packages/flask/app.py", line 2070, in wsgi_app
    response = self.full_dispatch_request()
  File "/usr/lib/python3/dist-packages/flask/app.py", line 1515, in full_dispatch_request
    rv = self.handle_user_exception(e)
  File "/usr/lib/python3/dist-packages/flask/app.py", line 1513, in full_dispatch_request
    rv = self.dispatch_request()
  File "/usr/lib/python3/dist-packages/flask/app.py", line 1499, in dispatch_request
    return self.ensure_sync(self.view_functions[rule.endpoint])(**req.view_args)
  File "/home/ultiv/Code/DevC/app.py", line 53, in balance
    return render_template("debug.html", debug=balance())
  File "/home/ultiv/Code/DevC/app.py", line 53, in balance
    return render_template("debug.html", debug=balance())
  File "/home/ultiv/Code/DevC/app.py", line 53, in balance
    return render_template("debug.html", debug=balance())
  [Previous line repeated 978 more times]
RecursionError: maximum recursion depth exceeded
[2023-06-22 16:25:29 +0700] [13500] [INFO] Worker reloading: /home/ultiv/Code/DevC/app.py modified
[2023-06-22 16:25:29 +0700] [13500] [INFO] Worker exiting (pid: 13500)
[2023-06-22 16:25:30 +0700] [13550] [INFO] Booting worker with pid: 13550
[2023-06-22 16:25:36,242] ERROR in app: Exception on /teams [GET]
Traceback (most recent call last):
  File "/usr/lib/python3/dist-packages/flask/app.py", line 2070, in wsgi_app
    response = self.full_dispatch_request()
  File "/usr/lib/python3/dist-packages/flask/app.py", line 1515, in full_dispatch_request
    rv = self.handle_user_exception(e)
  File "/usr/lib/python3/dist-packages/flask/app.py", line 1513, in full_dispatch_request
    rv = self.dispatch_request()
  File "/usr/lib/python3/dist-packages/flask/app.py", line 1499, in dispatch_request
    return self.ensure_sync(self.view_functions[rule.endpoint])(**req.view_args)
  File "/home/ultiv/Code/DevC/app.py", line 53, in balance
    teams = balance()
  File "/home/ultiv/Code/DevC/app.py", line 53, in balance
    teams = balance()
  File "/home/ultiv/Code/DevC/app.py", line 53, in balance
    teams = balance()
  [Previous line repeated 978 more times]
RecursionError: maximum recursion depth exceeded
[2023-06-22 16:26:07 +0700] [13550] [INFO] Worker reloading: /home/ultiv/Code/DevC/app.py modified
[2023-06-22 16:26:07 +0700] [13550] [INFO] Worker exiting (pid: 13550)
[2023-06-22 16:26:07 +0700] [13641] [INFO] Booting worker with pid: 13641
[2023-06-22 16:26:23 +0700] [13641] [INFO] Worker reloading: /home/ultiv/Code/DevC/app.py modified
[2023-06-22 16:26:23 +0700] [13641] [INFO] Worker exiting (pid: 13641)
[2023-06-22 16:26:23 +0700] [13654] [INFO] Booting worker with pid: 13654
[2023-06-22 16:27:34 +0700] [13654] [INFO] Worker reloading: /home/ultiv/Code/DevC/balance.py modified
[2023-06-22 16:27:34 +0700] [13654] [INFO] Worker exiting (pid: 13654)
[2023-06-22 16:27:35 +0700] [13706] [INFO] Booting worker with pid: 13706
[2023-06-22 16:31:28 +0700] [13169] [INFO] Handling signal: term
[2023-06-22 16:31:28 +0700] [13706] [INFO] Worker exiting (pid: 13706)
[2023-06-22 16:31:28 +0700] [13169] [INFO] Shutting down: Master
[2023-06-22 16:31:28 +0700] [13884] [INFO] Starting gunicorn 20.1.0
[2023-06-22 16:31:28 +0700] [13884] [INFO] Listening at: unix:/run/devc.sock (13884)
[2023-06-22 16:31:28 +0700] [13884] [INFO] Using worker: sync
[2023-06-22 16:31:28 +0700] [13885] [INFO] Booting worker with pid: 13885
[2023-06-22 16:31:30,554] ERROR in app: Exception on /teams [GET]
Traceback (most recent call last):
  File "/usr/lib/python3/dist-packages/flask/app.py", line 2070, in wsgi_app
    response = self.full_dispatch_request()
  File "/usr/lib/python3/dist-packages/flask/app.py", line 1515, in full_dispatch_request
    rv = self.handle_user_exception(e)
  File "/usr/lib/python3/dist-packages/flask/app.py", line 1513, in full_dispatch_request
    rv = self.dispatch_request()
  File "/usr/lib/python3/dist-packages/flask/app.py", line 1499, in dispatch_request
    return self.ensure_sync(self.view_functions[rule.endpoint])(**req.view_args)
  File "/home/ultiv/Code/DevC/app.py", line 54, in teams
    return render_template("teams.html", teams=teams)
  File "/usr/lib/python3/dist-packages/flask/templating.py", line 147, in render_template
    return _render(
  File "/usr/lib/python3/dist-packages/flask/templating.py", line 128, in _render
    rv = template.render(context)
  File "/usr/lib/python3/dist-packages/jinja2/environment.py", line 1291, in render
    self.environment.handle_exception()
  File "/usr/lib/python3/dist-packages/jinja2/environment.py", line 925, in handle_exception
    raise rewrite_traceback_stack(source=source)
  File "/home/ultiv/Code/DevC/templates/teams.html", line 1, in top-level template code
    {% extends 'base.html' %}
  File "/home/ultiv/Code/DevC/templates/base.html", line 14, in top-level template code
    {% block body %}{% endblock %}
  File "/home/ultiv/Code/DevC/templates/teams.html", line 17, in block 'body'
    <th>{{loop.parent.loop.index}}</th>
  File "/usr/lib/python3/dist-packages/jinja2/environment.py", line 474, in getattr
    return getattr(obj, attribute)
jinja2.exceptions.UndefinedError: 'jinja2.runtime.LoopContext object' has no attribute 'parent'
[2023-06-22 16:33:14,043] ERROR in app: Exception on /teams [GET]
Traceback (most recent call last):
  File "/usr/lib/python3/dist-packages/flask/app.py", line 2070, in wsgi_app
    response = self.full_dispatch_request()
  File "/usr/lib/python3/dist-packages/flask/app.py", line 1515, in full_dispatch_request
    rv = self.handle_user_exception(e)
  File "/usr/lib/python3/dist-packages/flask/app.py", line 1513, in full_dispatch_request
    rv = self.dispatch_request()
  File "/usr/lib/python3/dist-packages/flask/app.py", line 1499, in dispatch_request
    return self.ensure_sync(self.view_functions[rule.endpoint])(**req.view_args)
  File "/home/ultiv/Code/DevC/app.py", line 54, in teams
    return render_template("teams.html", teams=teams)
  File "/usr/lib/python3/dist-packages/flask/templating.py", line 147, in render_template
    return _render(
  File "/usr/lib/python3/dist-packages/flask/templating.py", line 128, in _render
    rv = template.render(context)
  File "/usr/lib/python3/dist-packages/jinja2/environment.py", line 1291, in render
    self.environment.handle_exception()
  File "/usr/lib/python3/dist-packages/jinja2/environment.py", line 925, in handle_exception
    raise rewrite_traceback_stack(source=source)
  File "/home/ultiv/Code/DevC/templates/teams.html", line 1, in top-level template code
    {% extends 'base.html' %}
  File "/home/ultiv/Code/DevC/templates/base.html", line 14, in top-level template code
    {% block body %}{% endblock %}
  File "/home/ultiv/Code/DevC/templates/teams.html", line 17, in block 'body'
    <tr>
  File "/usr/lib/python3/dist-packages/jinja2/environment.py", line 474, in getattr
    return getattr(obj, attribute)
jinja2.exceptions.UndefinedError: 'jinja2.runtime.LoopContext object' has no attribute 'parent'
[2023-06-22 16:35:04 +0700] [13885] [INFO] Worker reloading: /home/ultiv/Code/DevC/app.py modified
[2023-06-22 16:35:04 +0700] [13885] [INFO] Worker exiting (pid: 13885)
[2023-06-22 16:35:04 +0700] [14229] [INFO] Booting worker with pid: 14229
[2023-06-22 16:37:32 +0700] [14229] [INFO] Worker reloading: /home/ultiv/Code/DevC/app.py modified
[2023-06-22 16:37:32 +0700] [14229] [INFO] Worker exiting (pid: 14229)
[2023-06-22 16:37:33 +0700] [14329] [INFO] Booting worker with pid: 14329
[2023-06-22 16:37:36,063] ERROR in app: Exception on /teams [GET]
Traceback (most recent call last):
  File "/usr/lib/python3/dist-packages/flask/app.py", line 2070, in wsgi_app
    response = self.full_dispatch_request()
  File "/usr/lib/python3/dist-packages/flask/app.py", line 1515, in full_dispatch_request
    rv = self.handle_user_exception(e)
  File "/usr/lib/python3/dist-packages/flask/app.py", line 1513, in full_dispatch_request
    rv = self.dispatch_request()
  File "/usr/lib/python3/dist-packages/flask/app.py", line 1499, in dispatch_request
    return self.ensure_sync(self.view_functions[rule.endpoint])(**req.view_args)
  File "/home/ultiv/Code/DevC/app.py", line 54, in teams
    return render_template("teams.html", teams=teams)
  File "/usr/lib/python3/dist-packages/flask/templating.py", line 148, in render_template
    ctx.app.jinja_env.get_or_select_template(template_name_or_list),
  File "/usr/lib/python3/dist-packages/jinja2/environment.py", line 1068, in get_or_select_template
    return self.get_template(template_name_or_list, parent, globals)
  File "/usr/lib/python3/dist-packages/jinja2/environment.py", line 997, in get_template
    return self._load_template(name, globals)
  File "/usr/lib/python3/dist-packages/jinja2/environment.py", line 958, in _load_template
    template = self.loader.load(self, name, self.make_globals(globals))
  File "/usr/lib/python3/dist-packages/jinja2/loaders.py", line 137, in load
    code = environment.compile(source, name, filename)
  File "/usr/lib/python3/dist-packages/jinja2/environment.py", line 757, in compile
    self.handle_exception(source=source_hint)
  File "/usr/lib/python3/dist-packages/jinja2/environment.py", line 925, in handle_exception
    raise rewrite_traceback_stack(source=source)
  File "/home/ultiv/Code/DevC/templates/teams.html", line 22, in template
    {{}}
jinja2.exceptions.TemplateSyntaxError: Expected an expression, got 'end of print statement'
[2023-06-22 16:38:06 +0700] [14329] [INFO] Worker reloading: /home/ultiv/Code/DevC/app.py modified
[2023-06-22 16:38:06 +0700] [14329] [INFO] Worker exiting (pid: 14329)
[2023-06-22 16:38:06 +0700] [14352] [INFO] Booting worker with pid: 14352
[2023-06-22 16:38:10,087] ERROR in app: Exception on /teams [GET]
Traceback (most recent call last):
  File "/usr/lib/python3/dist-packages/flask/app.py", line 2070, in wsgi_app
    response = self.full_dispatch_request()
  File "/usr/lib/python3/dist-packages/flask/app.py", line 1515, in full_dispatch_request
    rv = self.handle_user_exception(e)
  File "/usr/lib/python3/dist-packages/flask/app.py", line 1513, in full_dispatch_request
    rv = self.dispatch_request()
  File "/usr/lib/python3/dist-packages/flask/app.py", line 1499, in dispatch_request
    return self.ensure_sync(self.view_functions[rule.endpoint])(**req.view_args)
  File "/home/ultiv/Code/DevC/app.py", line 54, in teams
    return render_template("teams.html", teams=teams)
  File "/usr/lib/python3/dist-packages/flask/templating.py", line 148, in render_template
    ctx.app.jinja_env.get_or_select_template(template_name_or_list),
  File "/usr/lib/python3/dist-packages/jinja2/environment.py", line 1068, in get_or_select_template
    return self.get_template(template_name_or_list, parent, globals)
  File "/usr/lib/python3/dist-packages/jinja2/environment.py", line 997, in get_template
    return self._load_template(name, globals)
  File "/usr/lib/python3/dist-packages/jinja2/environment.py", line 958, in _load_template
    template = self.loader.load(self, name, self.make_globals(globals))
  File "/usr/lib/python3/dist-packages/jinja2/loaders.py", line 137, in load
    code = environment.compile(source, name, filename)
  File "/usr/lib/python3/dist-packages/jinja2/environment.py", line 757, in compile
    self.handle_exception(source=source_hint)
  File "/usr/lib/python3/dist-packages/jinja2/environment.py", line 925, in handle_exception
    raise rewrite_traceback_stack(source=source)
  File "/home/ultiv/Code/DevC/templates/teams.html", line 22, in template
    {{ }}
jinja2.exceptions.TemplateSyntaxError: Expected an expression, got 'end of print statement'
[2023-06-22 16:39:28 +0700] [14352] [INFO] Worker reloading: /home/ultiv/Code/DevC/app.py modified
[2023-06-22 16:39:28 +0700] [14352] [INFO] Worker exiting (pid: 14352)
[2023-06-22 16:39:28 +0700] [14403] [INFO] Booting worker with pid: 14403
[2023-06-22 16:39:28 +0700] [14403] [ERROR] invalid syntax (app.py, line 54)
Traceback (most recent call last):
  File "/usr/lib/python3/dist-packages/gunicorn/workers/base.py", line 146, in load_wsgi
    self.wsgi = self.app.wsgi()
  File "/usr/lib/python3/dist-packages/gunicorn/app/base.py", line 67, in wsgi
    self.callable = self.load()
  File "/usr/lib/python3/dist-packages/gunicorn/app/wsgiapp.py", line 58, in load
    return self.load_wsgiapp()
  File "/usr/lib/python3/dist-packages/gunicorn/app/wsgiapp.py", line 48, in load_wsgiapp
    return util.import_app(self.app_uri)
  File "/usr/lib/python3/dist-packages/gunicorn/util.py", line 384, in import_app
    mod = importlib.import_module(module)
  File "/usr/lib/python3.10/importlib/__init__.py", line 126, in import_module
    return _bootstrap._gcd_import(name[level:], package, level)
  File "<frozen importlib._bootstrap>", line 1050, in _gcd_import
  File "<frozen importlib._bootstrap>", line 1027, in _find_and_load
  File "<frozen importlib._bootstrap>", line 1006, in _find_and_load_unlocked
  File "<frozen importlib._bootstrap>", line 688, in _load_unlocked
  File "<frozen importlib._bootstrap_external>", line 879, in exec_module
  File "<frozen importlib._bootstrap_external>", line 1017, in get_code
  File "<frozen importlib._bootstrap_external>", line 947, in source_to_code
  File "<frozen importlib._bootstrap>", line 241, in _call_with_frames_removed
  File "/home/ultiv/Code/DevC/app.py", line 54
    return render_template("teams.html", teams=teams).
                                                      ^
SyntaxError: invalid syntax
[2023-06-22 16:39:29 +0700] [14403] [INFO] Worker reloading: /home/ultiv/Code/DevC/app.py modified
[2023-06-22 16:39:29 +0700] [14403] [INFO] Worker exiting (pid: 14403)
[2023-06-22 16:39:29 +0700] [14405] [INFO] Booting worker with pid: 14405
[2023-06-22 16:39:31,677] ERROR in app: Exception on /teams [GET]
Traceback (most recent call last):
  File "/usr/lib/python3/dist-packages/flask/app.py", line 2070, in wsgi_app
    response = self.full_dispatch_request()
  File "/usr/lib/python3/dist-packages/flask/app.py", line 1515, in full_dispatch_request
    rv = self.handle_user_exception(e)
  File "/usr/lib/python3/dist-packages/flask/app.py", line 1513, in full_dispatch_request
    rv = self.dispatch_request()
  File "/usr/lib/python3/dist-packages/flask/app.py", line 1499, in dispatch_request
    return self.ensure_sync(self.view_functions[rule.endpoint])(**req.view_args)
  File "/home/ultiv/Code/DevC/app.py", line 54, in teams
    return render_template("teams.html", teams=teams)
  File "/usr/lib/python3/dist-packages/flask/templating.py", line 148, in render_template
    ctx.app.jinja_env.get_or_select_template(template_name_or_list),
  File "/usr/lib/python3/dist-packages/jinja2/environment.py", line 1068, in get_or_select_template
    return self.get_template(template_name_or_list, parent, globals)
  File "/usr/lib/python3/dist-packages/jinja2/environment.py", line 997, in get_template
    return self._load_template(name, globals)
  File "/usr/lib/python3/dist-packages/jinja2/environment.py", line 958, in _load_template
    template = self.loader.load(self, name, self.make_globals(globals))
  File "/usr/lib/python3/dist-packages/jinja2/loaders.py", line 137, in load
    code = environment.compile(source, name, filename)
  File "/usr/lib/python3/dist-packages/jinja2/environment.py", line 757, in compile
    self.handle_exception(source=source_hint)
  File "/usr/lib/python3/dist-packages/jinja2/environment.py", line 925, in handle_exception
    raise rewrite_traceback_stack(source=source)
  File "/home/ultiv/Code/DevC/templates/teams.html", line 30, in template
    {% endfor %}
jinja2.exceptions.TemplateSyntaxError: Encountered unknown tag 'endfor'. You probably made a nesting mistake. Jinja is expecting this tag, but currently looking for 'endif'. The innermost block that needs to be closed is 'if'.
[2023-06-22 16:40:15 +0700] [14405] [INFO] Worker reloading: /home/ultiv/Code/DevC/app.py modified
[2023-06-22 16:40:15 +0700] [14405] [INFO] Worker exiting (pid: 14405)
[2023-06-22 16:40:15 +0700] [14473] [INFO] Booting worker with pid: 14473
[2023-06-22 16:47:35 +0700] [14473] [INFO] Worker reloading: /home/ultiv/Code/DevC/app.py modified
[2023-06-22 16:47:35 +0700] [14473] [INFO] Worker exiting (pid: 14473)
[2023-06-22 16:47:36 +0700] [14795] [INFO] Booting worker with pid: 14795
[2023-06-22 16:47:36 +0700] [14795] [ERROR] Exception in worker process
Traceback (most recent call last):
  File "/usr/lib/python3/dist-packages/gunicorn/arbiter.py", line 589, in spawn_worker
    worker.init_process()
  File "/usr/lib/python3/dist-packages/gunicorn/workers/base.py", line 134, in init_process
    self.load_wsgi()
  File "/usr/lib/python3/dist-packages/gunicorn/workers/base.py", line 146, in load_wsgi
    self.wsgi = self.app.wsgi()
  File "/usr/lib/python3/dist-packages/gunicorn/app/base.py", line 67, in wsgi
    self.callable = self.load()
  File "/usr/lib/python3/dist-packages/gunicorn/app/wsgiapp.py", line 58, in load
    return self.load_wsgiapp()
  File "/usr/lib/python3/dist-packages/gunicorn/app/wsgiapp.py", line 48, in load_wsgiapp
    return util.import_app(self.app_uri)
  File "/usr/lib/python3/dist-packages/gunicorn/util.py", line 384, in import_app
    mod = importlib.import_module(module)
  File "/usr/lib/python3.10/importlib/__init__.py", line 126, in import_module
    return _bootstrap._gcd_import(name[level:], package, level)
  File "<frozen importlib._bootstrap>", line 1050, in _gcd_import
  File "<frozen importlib._bootstrap>", line 1027, in _find_and_load
  File "<frozen importlib._bootstrap>", line 1006, in _find_and_load_unlocked
  File "<frozen importlib._bootstrap>", line 688, in _load_unlocked
  File "<frozen importlib._bootstrap_external>", line 883, in exec_module
  File "<frozen importlib._bootstrap>", line 241, in _call_with_frames_removed
  File "/home/ultiv/Code/DevC/app.py", line 58, in <module>
    def bracket():
  File "/usr/lib/python3/dist-packages/flask/scaffold.py", line 435, in decorator
    self.add_url_rule(rule, endpoint, f, **options)
  File "/usr/lib/python3/dist-packages/flask/scaffold.py", line 56, in wrapper_func
    return f(self, *args, **kwargs)
  File "/usr/lib/python3/dist-packages/flask/app.py", line 1085, in add_url_rule
    rule = self.url_rule_class(rule, methods=methods, **options)
  File "/usr/lib/python3/dist-packages/werkzeug/routing.py", line 697, in __init__
    raise ValueError("urls must start with a leading slash")
ValueError: urls must start with a leading slash
[2023-06-22 16:47:36 +0700] [14795] [INFO] Worker exiting (pid: 14795)
[2023-06-22 16:47:36 +0700] [13884] [INFO] Shutting down: Master
[2023-06-22 16:47:36 +0700] [13884] [INFO] Reason: Worker failed to boot.
[2023-06-27 16:20:59 +0700] [5211] [INFO] Starting gunicorn 20.1.0
[2023-06-27 16:20:59 +0700] [5211] [INFO] Listening at: unix:/run/devc.sock (5211)
[2023-06-27 16:20:59 +0700] [5211] [INFO] Using worker: sync
[2023-06-27 16:20:59 +0700] [5212] [INFO] Booting worker with pid: 5212
[2023-06-27 16:21:00 +0700] [5212] [ERROR] Exception in worker process
Traceback (most recent call last):
  File "/usr/lib/python3/dist-packages/gunicorn/arbiter.py", line 589, in spawn_worker
    worker.init_process()
  File "/usr/lib/python3/dist-packages/gunicorn/workers/base.py", line 134, in init_process
    self.load_wsgi()
  File "/usr/lib/python3/dist-packages/gunicorn/workers/base.py", line 146, in load_wsgi
    self.wsgi = self.app.wsgi()
  File "/usr/lib/python3/dist-packages/gunicorn/app/base.py", line 67, in wsgi
    self.callable = self.load()
  File "/usr/lib/python3/dist-packages/gunicorn/app/wsgiapp.py", line 58, in load
    return self.load_wsgiapp()
  File "/usr/lib/python3/dist-packages/gunicorn/app/wsgiapp.py", line 48, in load_wsgiapp
    return util.import_app(self.app_uri)
  File "/usr/lib/python3/dist-packages/gunicorn/util.py", line 384, in import_app
    mod = importlib.import_module(module)
  File "/usr/lib/python3.10/importlib/__init__.py", line 126, in import_module
    return _bootstrap._gcd_import(name[level:], package, level)
  File "<frozen importlib._bootstrap>", line 1050, in _gcd_import
  File "<frozen importlib._bootstrap>", line 1027, in _find_and_load
  File "<frozen importlib._bootstrap>", line 1006, in _find_and_load_unlocked
  File "<frozen importlib._bootstrap>", line 688, in _load_unlocked
  File "<frozen importlib._bootstrap_external>", line 883, in exec_module
  File "<frozen importlib._bootstrap>", line 241, in _call_with_frames_removed
  File "/home/ultiv/Code/DevC/app.py", line 58, in <module>
    def bracket():
  File "/usr/lib/python3/dist-packages/flask/scaffold.py", line 435, in decorator
    self.add_url_rule(rule, endpoint, f, **options)
  File "/usr/lib/python3/dist-packages/flask/scaffold.py", line 56, in wrapper_func
    return f(self, *args, **kwargs)
  File "/usr/lib/python3/dist-packages/flask/app.py", line 1085, in add_url_rule
    rule = self.url_rule_class(rule, methods=methods, **options)
  File "/usr/lib/python3/dist-packages/werkzeug/routing.py", line 697, in __init__
    raise ValueError("urls must start with a leading slash")
ValueError: urls must start with a leading slash
[2023-06-27 16:21:00 +0700] [5212] [INFO] Worker exiting (pid: 5212)
[2023-06-27 16:21:00 +0700] [5211] [INFO] Shutting down: Master
[2023-06-27 16:21:00 +0700] [5211] [INFO] Reason: Worker failed to boot.
[2023-06-27 16:21:00 +0700] [5220] [INFO] Starting gunicorn 20.1.0
[2023-06-27 16:21:00 +0700] [5220] [INFO] Listening at: unix:/run/devc.sock (5220)
[2023-06-27 16:21:00 +0700] [5220] [INFO] Using worker: sync
[2023-06-27 16:21:00 +0700] [5221] [INFO] Booting worker with pid: 5221
[2023-06-27 16:21:00 +0700] [5221] [ERROR] Exception in worker process
Traceback (most recent call last):
  File "/usr/lib/python3/dist-packages/gunicorn/arbiter.py", line 589, in spawn_worker
    worker.init_process()
  File "/usr/lib/python3/dist-packages/gunicorn/workers/base.py", line 134, in init_process
    self.load_wsgi()
  File "/usr/lib/python3/dist-packages/gunicorn/workers/base.py", line 146, in load_wsgi
    self.wsgi = self.app.wsgi()
  File "/usr/lib/python3/dist-packages/gunicorn/app/base.py", line 67, in wsgi
    self.callable = self.load()
  File "/usr/lib/python3/dist-packages/gunicorn/app/wsgiapp.py", line 58, in load
    return self.load_wsgiapp()
  File "/usr/lib/python3/dist-packages/gunicorn/app/wsgiapp.py", line 48, in load_wsgiapp
    return util.import_app(self.app_uri)
  File "/usr/lib/python3/dist-packages/gunicorn/util.py", line 384, in import_app
    mod = importlib.import_module(module)
  File "/usr/lib/python3.10/importlib/__init__.py", line 126, in import_module
    return _bootstrap._gcd_import(name[level:], package, level)
  File "<frozen importlib._bootstrap>", line 1050, in _gcd_import
  File "<frozen importlib._bootstrap>", line 1027, in _find_and_load
  File "<frozen importlib._bootstrap>", line 1006, in _find_and_load_unlocked
  File "<frozen importlib._bootstrap>", line 688, in _load_unlocked
  File "<frozen importlib._bootstrap_external>", line 883, in exec_module
  File "<frozen importlib._bootstrap>", line 241, in _call_with_frames_removed
  File "/home/ultiv/Code/DevC/app.py", line 58, in <module>
    def bracket():
  File "/usr/lib/python3/dist-packages/flask/scaffold.py", line 435, in decorator
    self.add_url_rule(rule, endpoint, f, **options)
  File "/usr/lib/python3/dist-packages/flask/scaffold.py", line 56, in wrapper_func
    return f(self, *args, **kwargs)
  File "/usr/lib/python3/dist-packages/flask/app.py", line 1085, in add_url_rule
    rule = self.url_rule_class(rule, methods=methods, **options)
  File "/usr/lib/python3/dist-packages/werkzeug/routing.py", line 697, in __init__
    raise ValueError("urls must start with a leading slash")
ValueError: urls must start with a leading slash
[2023-06-27 16:21:00 +0700] [5221] [INFO] Worker exiting (pid: 5221)
[2023-06-27 16:21:01 +0700] [5220] [INFO] Shutting down: Master
[2023-06-27 16:21:01 +0700] [5220] [INFO] Reason: Worker failed to boot.
[2023-06-27 16:21:01 +0700] [5229] [INFO] Starting gunicorn 20.1.0
[2023-06-27 16:21:01 +0700] [5229] [INFO] Listening at: unix:/run/devc.sock (5229)
[2023-06-27 16:21:01 +0700] [5229] [INFO] Using worker: sync
[2023-06-27 16:21:01 +0700] [5234] [INFO] Booting worker with pid: 5234
[2023-06-27 16:21:01 +0700] [5234] [ERROR] Exception in worker process
Traceback (most recent call last):
  File "/usr/lib/python3/dist-packages/gunicorn/arbiter.py", line 589, in spawn_worker
    worker.init_process()
  File "/usr/lib/python3/dist-packages/gunicorn/workers/base.py", line 134, in init_process
    self.load_wsgi()
  File "/usr/lib/python3/dist-packages/gunicorn/workers/base.py", line 146, in load_wsgi
    self.wsgi = self.app.wsgi()
  File "/usr/lib/python3/dist-packages/gunicorn/app/base.py", line 67, in wsgi
    self.callable = self.load()
  File "/usr/lib/python3/dist-packages/gunicorn/app/wsgiapp.py", line 58, in load
    return self.load_wsgiapp()
  File "/usr/lib/python3/dist-packages/gunicorn/app/wsgiapp.py", line 48, in load_wsgiapp
    return util.import_app(self.app_uri)
  File "/usr/lib/python3/dist-packages/gunicorn/util.py", line 384, in import_app
    mod = importlib.import_module(module)
  File "/usr/lib/python3.10/importlib/__init__.py", line 126, in import_module
    return _bootstrap._gcd_import(name[level:], package, level)
  File "<frozen importlib._bootstrap>", line 1050, in _gcd_import
  File "<frozen importlib._bootstrap>", line 1027, in _find_and_load
  File "<frozen importlib._bootstrap>", line 1006, in _find_and_load_unlocked
  File "<frozen importlib._bootstrap>", line 688, in _load_unlocked
  File "<frozen importlib._bootstrap_external>", line 883, in exec_module
  File "<frozen importlib._bootstrap>", line 241, in _call_with_frames_removed
  File "/home/ultiv/Code/DevC/app.py", line 58, in <module>
    def bracket():
  File "/usr/lib/python3/dist-packages/flask/scaffold.py", line 435, in decorator
    self.add_url_rule(rule, endpoint, f, **options)
  File "/usr/lib/python3/dist-packages/flask/scaffold.py", line 56, in wrapper_func
    return f(self, *args, **kwargs)
  File "/usr/lib/python3/dist-packages/flask/app.py", line 1085, in add_url_rule
    rule = self.url_rule_class(rule, methods=methods, **options)
  File "/usr/lib/python3/dist-packages/werkzeug/routing.py", line 697, in __init__
    raise ValueError("urls must start with a leading slash")
ValueError: urls must start with a leading slash
[2023-06-27 16:21:01 +0700] [5234] [INFO] Worker exiting (pid: 5234)
[2023-06-27 16:21:02 +0700] [5229] [INFO] Shutting down: Master
[2023-06-27 16:21:02 +0700] [5229] [INFO] Reason: Worker failed to boot.
[2023-06-27 16:21:02 +0700] [5242] [INFO] Starting gunicorn 20.1.0
[2023-06-27 16:21:02 +0700] [5242] [INFO] Listening at: unix:/run/devc.sock (5242)
[2023-06-27 16:21:02 +0700] [5242] [INFO] Using worker: sync
[2023-06-27 16:21:02 +0700] [5243] [INFO] Booting worker with pid: 5243
[2023-06-27 16:21:02 +0700] [5243] [ERROR] Exception in worker process
Traceback (most recent call last):
  File "/usr/lib/python3/dist-packages/gunicorn/arbiter.py", line 589, in spawn_worker
    worker.init_process()
  File "/usr/lib/python3/dist-packages/gunicorn/workers/base.py", line 134, in init_process
    self.load_wsgi()
  File "/usr/lib/python3/dist-packages/gunicorn/workers/base.py", line 146, in load_wsgi
    self.wsgi = self.app.wsgi()
  File "/usr/lib/python3/dist-packages/gunicorn/app/base.py", line 67, in wsgi
    self.callable = self.load()
  File "/usr/lib/python3/dist-packages/gunicorn/app/wsgiapp.py", line 58, in load
    return self.load_wsgiapp()
  File "/usr/lib/python3/dist-packages/gunicorn/app/wsgiapp.py", line 48, in load_wsgiapp
    return util.import_app(self.app_uri)
  File "/usr/lib/python3/dist-packages/gunicorn/util.py", line 384, in import_app
    mod = importlib.import_module(module)
  File "/usr/lib/python3.10/importlib/__init__.py", line 126, in import_module
    return _bootstrap._gcd_import(name[level:], package, level)
  File "<frozen importlib._bootstrap>", line 1050, in _gcd_import
  File "<frozen importlib._bootstrap>", line 1027, in _find_and_load
  File "<frozen importlib._bootstrap>", line 1006, in _find_and_load_unlocked
  File "<frozen importlib._bootstrap>", line 688, in _load_unlocked
  File "<frozen importlib._bootstrap_external>", line 883, in exec_module
  File "<frozen importlib._bootstrap>", line 241, in _call_with_frames_removed
  File "/home/ultiv/Code/DevC/app.py", line 58, in <module>
    def bracket():
  File "/usr/lib/python3/dist-packages/flask/scaffold.py", line 435, in decorator
    self.add_url_rule(rule, endpoint, f, **options)
  File "/usr/lib/python3/dist-packages/flask/scaffold.py", line 56, in wrapper_func
    return f(self, *args, **kwargs)
  File "/usr/lib/python3/dist-packages/flask/app.py", line 1085, in add_url_rule
    rule = self.url_rule_class(rule, methods=methods, **options)
  File "/usr/lib/python3/dist-packages/werkzeug/routing.py", line 697, in __init__
    raise ValueError("urls must start with a leading slash")
ValueError: urls must start with a leading slash
[2023-06-27 16:21:02 +0700] [5243] [INFO] Worker exiting (pid: 5243)
[2023-06-27 16:21:03 +0700] [5242] [INFO] Shutting down: Master
[2023-06-27 16:21:03 +0700] [5242] [INFO] Reason: Worker failed to boot.
[2023-06-27 16:21:03 +0700] [5251] [INFO] Starting gunicorn 20.1.0
[2023-06-27 16:21:03 +0700] [5251] [INFO] Listening at: unix:/run/devc.sock (5251)
[2023-06-27 16:21:03 +0700] [5251] [INFO] Using worker: sync
[2023-06-27 16:21:03 +0700] [5252] [INFO] Booting worker with pid: 5252
[2023-06-27 16:21:03 +0700] [5252] [ERROR] Exception in worker process
Traceback (most recent call last):
  File "/usr/lib/python3/dist-packages/gunicorn/arbiter.py", line 589, in spawn_worker
    worker.init_process()
  File "/usr/lib/python3/dist-packages/gunicorn/workers/base.py", line 134, in init_process
    self.load_wsgi()
  File "/usr/lib/python3/dist-packages/gunicorn/workers/base.py", line 146, in load_wsgi
    self.wsgi = self.app.wsgi()
  File "/usr/lib/python3/dist-packages/gunicorn/app/base.py", line 67, in wsgi
    self.callable = self.load()
  File "/usr/lib/python3/dist-packages/gunicorn/app/wsgiapp.py", line 58, in load
    return self.load_wsgiapp()
  File "/usr/lib/python3/dist-packages/gunicorn/app/wsgiapp.py", line 48, in load_wsgiapp
    return util.import_app(self.app_uri)
  File "/usr/lib/python3/dist-packages/gunicorn/util.py", line 384, in import_app
    mod = importlib.import_module(module)
  File "/usr/lib/python3.10/importlib/__init__.py", line 126, in import_module
    return _bootstrap._gcd_import(name[level:], package, level)
  File "<frozen importlib._bootstrap>", line 1050, in _gcd_import
  File "<frozen importlib._bootstrap>", line 1027, in _find_and_load
  File "<frozen importlib._bootstrap>", line 1006, in _find_and_load_unlocked
  File "<frozen importlib._bootstrap>", line 688, in _load_unlocked
  File "<frozen importlib._bootstrap_external>", line 883, in exec_module
  File "<frozen importlib._bootstrap>", line 241, in _call_with_frames_removed
  File "/home/ultiv/Code/DevC/app.py", line 58, in <module>
    def bracket():
  File "/usr/lib/python3/dist-packages/flask/scaffold.py", line 435, in decorator
    self.add_url_rule(rule, endpoint, f, **options)
  File "/usr/lib/python3/dist-packages/flask/scaffold.py", line 56, in wrapper_func
    return f(self, *args, **kwargs)
  File "/usr/lib/python3/dist-packages/flask/app.py", line 1085, in add_url_rule
    rule = self.url_rule_class(rule, methods=methods, **options)
  File "/usr/lib/python3/dist-packages/werkzeug/routing.py", line 697, in __init__
    raise ValueError("urls must start with a leading slash")
ValueError: urls must start with a leading slash
[2023-06-27 16:21:03 +0700] [5252] [INFO] Worker exiting (pid: 5252)
[2023-06-27 16:21:03 +0700] [5251] [INFO] Shutting down: Master
[2023-06-27 16:21:03 +0700] [5251] [INFO] Reason: Worker failed to boot.
[2023-06-27 16:22:07 +0700] [6521] [INFO] Starting gunicorn 20.1.0
[2023-06-27 16:22:07 +0700] [6521] [INFO] Listening at: unix:/run/devc.sock (6521)
[2023-06-27 16:22:07 +0700] [6521] [INFO] Using worker: sync
[2023-06-27 16:22:07 +0700] [6522] [INFO] Booting worker with pid: 6522
[2023-06-27 16:22:10 +0700] [6522] [ERROR] Error handling request
Traceback (most recent call last):
  File "/usr/lib/python3/dist-packages/gunicorn/workers/sync.py", line 182, in handle_request
    resp.write_file(respiter)
  File "/usr/lib/python3/dist-packages/gunicorn/http/wsgi.py", line 385, in write_file
    if not self.sendfile(respiter):
  File "/usr/lib/python3/dist-packages/gunicorn/http/wsgi.py", line 375, in sendfile
    self.sock.sendfile(respiter.filelike, count=nbytes)
  File "/usr/lib/python3.10/socket.py", line 484, in sendfile
    return self._sendfile_use_sendfile(file, offset, count)
  File "/usr/lib/python3.10/socket.py", line 348, in _sendfile_use_sendfile
    self._check_sendfile_params(file, offset, count)
  File "/usr/lib/python3.10/socket.py", line 462, in _check_sendfile_params
    raise ValueError(
ValueError: count must be a positive integer (got 0)
[2023-06-27 16:22:20,496] ERROR in app: Exception on /teams [GET]
Traceback (most recent call last):
  File "/usr/lib/python3/dist-packages/flask/app.py", line 2070, in wsgi_app
    response = self.full_dispatch_request()
  File "/usr/lib/python3/dist-packages/flask/app.py", line 1515, in full_dispatch_request
    rv = self.handle_user_exception(e)
  File "/usr/lib/python3/dist-packages/flask/app.py", line 1513, in full_dispatch_request
    rv = self.dispatch_request()
  File "/usr/lib/python3/dist-packages/flask/app.py", line 1499, in dispatch_request
    return self.ensure_sync(self.view_functions[rule.endpoint])(**req.view_args)
  File "/home/ultiv/Code/DevC/app.py", line 54, in teams
    return render_template("teams.html", teams=teams)
  File "/usr/lib/python3/dist-packages/flask/templating.py", line 148, in render_template
    ctx.app.jinja_env.get_or_select_template(template_name_or_list),
  File "/usr/lib/python3/dist-packages/jinja2/environment.py", line 1068, in get_or_select_template
    return self.get_template(template_name_or_list, parent, globals)
  File "/usr/lib/python3/dist-packages/jinja2/environment.py", line 997, in get_template
    return self._load_template(name, globals)
  File "/usr/lib/python3/dist-packages/jinja2/environment.py", line 958, in _load_template
    template = self.loader.load(self, name, self.make_globals(globals))
  File "/usr/lib/python3/dist-packages/jinja2/loaders.py", line 137, in load
    code = environment.compile(source, name, filename)
  File "/usr/lib/python3/dist-packages/jinja2/environment.py", line 757, in compile
    self.handle_exception(source=source_hint)
  File "/usr/lib/python3/dist-packages/jinja2/environment.py", line 925, in handle_exception
    raise rewrite_traceback_stack(source=source)
  File "/home/ultiv/Code/DevC/templates/teams.html", line 22, in template
    {{}}
jinja2.exceptions.TemplateSyntaxError: Expected an expression, got 'end of print statement'
[2023-06-27 16:24:02 +0700] [6521] [INFO] Handling signal: term
[2023-06-27 16:24:02 +0700] [6522] [INFO] Worker exiting (pid: 6522)
[2023-06-27 16:24:02 +0700] [6521] [INFO] Shutting down: Master
[2023-06-27 16:24:03 +0700] [6737] [INFO] Starting gunicorn 20.1.0
[2023-06-27 16:24:03 +0700] [6737] [INFO] Listening at: unix:/run/devc.sock (6737)
[2023-06-27 16:24:03 +0700] [6737] [INFO] Using worker: sync
[2023-06-27 16:24:03 +0700] [6738] [INFO] Booting worker with pid: 6738
[2023-06-27 16:30:20 +0700] [6738] [ERROR] Error handling request
Traceback (most recent call last):
  File "/usr/lib/python3/dist-packages/gunicorn/workers/sync.py", line 182, in handle_request
    resp.write_file(respiter)
  File "/usr/lib/python3/dist-packages/gunicorn/http/wsgi.py", line 385, in write_file
    if not self.sendfile(respiter):
  File "/usr/lib/python3/dist-packages/gunicorn/http/wsgi.py", line 375, in sendfile
    self.sock.sendfile(respiter.filelike, count=nbytes)
  File "/usr/lib/python3.10/socket.py", line 484, in sendfile
    return self._sendfile_use_sendfile(file, offset, count)
  File "/usr/lib/python3.10/socket.py", line 348, in _sendfile_use_sendfile
    self._check_sendfile_params(file, offset, count)
  File "/usr/lib/python3.10/socket.py", line 462, in _check_sendfile_params
    raise ValueError(
ValueError: count must be a positive integer (got 0)
[2023-06-27 17:25:03 +0700] [6737] [INFO] Handling signal: term
[2023-06-27 17:25:03 +0700] [6738] [INFO] Worker exiting (pid: 6738)
[2023-06-27 17:25:04 +0700] [6737] [INFO] Shutting down: Master
[2023-06-28 12:33:59 +0700] [4847] [INFO] Starting gunicorn 20.1.0
[2023-06-28 12:33:59 +0700] [4847] [INFO] Listening at: unix:/run/devc.sock (4847)
[2023-06-28 12:33:59 +0700] [4847] [INFO] Using worker: sync
[2023-06-28 12:33:59 +0700] [4848] [INFO] Booting worker with pid: 4848
[2023-06-28 12:36:29,193] ERROR in app: Exception on /players [GET]
Traceback (most recent call last):
  File "/usr/lib/python3/dist-packages/flask/app.py", line 2070, in wsgi_app
    response = self.full_dispatch_request()
  File "/usr/lib/python3/dist-packages/flask/app.py", line 1515, in full_dispatch_request
    rv = self.handle_user_exception(e)
  File "/usr/lib/python3/dist-packages/flask/app.py", line 1513, in full_dispatch_request
    rv = self.dispatch_request()
  File "/usr/lib/python3/dist-packages/flask/app.py", line 1499, in dispatch_request
    return self.ensure_sync(self.view_functions[rule.endpoint])(**req.view_args)
  File "/home/ultiv/Code/DevC/app.py", line 30, in get_players
    player["rank"] = ranks[player["rank"] - 1]
TypeError: unsupported operand type(s) for -: 'str' and 'int'
[2023-06-28 12:36:36,858] ERROR in app: Exception on /players [GET]
Traceback (most recent call last):
  File "/usr/lib/python3/dist-packages/flask/app.py", line 2070, in wsgi_app
    response = self.full_dispatch_request()
  File "/usr/lib/python3/dist-packages/flask/app.py", line 1515, in full_dispatch_request
    rv = self.handle_user_exception(e)
  File "/usr/lib/python3/dist-packages/flask/app.py", line 1513, in full_dispatch_request
    rv = self.dispatch_request()
  File "/usr/lib/python3/dist-packages/flask/app.py", line 1499, in dispatch_request
    return self.ensure_sync(self.view_functions[rule.endpoint])(**req.view_args)
  File "/home/ultiv/Code/DevC/app.py", line 30, in get_players
    player["rank"] = ranks[player["rank"] - 1]
TypeError: unsupported operand type(s) for -: 'str' and 'int'
[2023-06-28 12:39:51 +0700] [4847] [CRITICAL] WORKER TIMEOUT (pid:4848)
[2023-06-28 12:39:51 +0700] [4848] [INFO] Worker exiting (pid: 4848)
[2023-06-28 12:39:51 +0700] [5586] [INFO] Booting worker with pid: 5586
[2023-06-28 12:40:04 +0700] [4847] [INFO] Handling signal: term
[2023-06-28 12:40:04 +0700] [5586] [INFO] Worker exiting (pid: 5586)
[2023-06-28 12:40:04 +0700] [4847] [INFO] Shutting down: Master
[2023-07-02 13:04:11 +0700] [4082] [INFO] Starting gunicorn 20.1.0
[2023-07-02 13:04:11 +0700] [4082] [INFO] Listening at: unix:/run/devc.sock (4082)
[2023-07-02 13:04:11 +0700] [4082] [INFO] Using worker: sync
[2023-07-02 13:04:11 +0700] [4083] [INFO] Booting worker with pid: 4083
[2023-07-02 13:04:57,999] ERROR in app: Exception on /players [GET]
Traceback (most recent call last):
  File "/usr/lib/python3/dist-packages/flask/app.py", line 2070, in wsgi_app
    response = self.full_dispatch_request()
  File "/usr/lib/python3/dist-packages/flask/app.py", line 1515, in full_dispatch_request
    rv = self.handle_user_exception(e)
  File "/usr/lib/python3/dist-packages/flask/app.py", line 1513, in full_dispatch_request
    rv = self.dispatch_request()
  File "/usr/lib/python3/dist-packages/flask/app.py", line 1499, in dispatch_request
    return self.ensure_sync(self.view_functions[rule.endpoint])(**req.view_args)
  File "/home/ultiv/Code/DevC/app.py", line 30, in get_players
    player["rank"] = ranks[player["rank"] - 1]
TypeError: unsupported operand type(s) for -: 'str' and 'int'
[2023-07-02 13:05:49,381] ERROR in app: Exception on /players [GET]
Traceback (most recent call last):
  File "/usr/lib/python3/dist-packages/flask/app.py", line 2070, in wsgi_app
    response = self.full_dispatch_request()
  File "/usr/lib/python3/dist-packages/flask/app.py", line 1515, in full_dispatch_request
    rv = self.handle_user_exception(e)
  File "/usr/lib/python3/dist-packages/flask/app.py", line 1513, in full_dispatch_request
    rv = self.dispatch_request()
  File "/usr/lib/python3/dist-packages/flask/app.py", line 1499, in dispatch_request
    return self.ensure_sync(self.view_functions[rule.endpoint])(**req.view_args)
  File "/home/ultiv/Code/DevC/app.py", line 30, in get_players
    player["rank"] = ranks[player["rank"] - 1]
TypeError: unsupported operand type(s) for -: 'str' and 'int'
[2023-07-02 13:07:04 +0700] [4083] [INFO] Worker reloading: /home/ultiv/Code/DevC/app.py modified
[2023-07-02 13:07:04 +0700] [4083] [INFO] Worker exiting (pid: 4083)
[2023-07-02 13:07:04 +0700] [4289] [INFO] Booting worker with pid: 4289
[2023-07-02 13:07:18 +0700] [4289] [INFO] Worker reloading: /home/ultiv/Code/DevC/app.py modified
[2023-07-02 13:07:18 +0700] [4289] [INFO] Worker exiting (pid: 4289)
[2023-07-02 13:07:19 +0700] [4305] [INFO] Booting worker with pid: 4305
[2023-07-02 13:09:58 +0700] [4305] [INFO] Worker reloading: /home/ultiv/Code/DevC/db_utils.py modified
[2023-07-02 13:09:58 +0700] [4305] [INFO] Worker exiting (pid: 4305)
[2023-07-02 13:09:58 +0700] [4364] [INFO] Booting worker with pid: 4364
[2023-07-02 13:20:02 +0700] [4364] [INFO] Worker reloading: /home/ultiv/Code/DevC/app.py modified
[2023-07-02 13:20:02 +0700] [4364] [INFO] Worker exiting (pid: 4364)
[2023-07-02 13:20:03 +0700] [4494] [INFO] Booting worker with pid: 4494
[2023-07-02 13:21:45 +0700] [4494] [INFO] Worker reloading: /home/ultiv/Code/DevC/lol.py modified
[2023-07-02 13:21:45 +0700] [4494] [INFO] Worker exiting (pid: 4494)
[2023-07-02 13:21:46 +0700] [4541] [INFO] Booting worker with pid: 4541
[2023-07-02 13:21:53 +0700] [4541] [INFO] Worker reloading: /home/ultiv/Code/DevC/lol.py modified
[2023-07-02 13:21:53 +0700] [4541] [INFO] Worker exiting (pid: 4541)
[2023-07-02 13:21:54 +0700] [4550] [INFO] Booting worker with pid: 4550
[2023-07-02 13:27:38 +0700] [4550] [INFO] Worker reloading: /home/ultiv/Code/DevC/lol.py modified
[2023-07-02 13:27:38 +0700] [4550] [INFO] Worker exiting (pid: 4550)
[2023-07-02 13:27:38 +0700] [4620] [INFO] Booting worker with pid: 4620
[2023-07-02 13:31:48 +0700] [4620] [INFO] Worker reloading: /home/ultiv/Code/DevC/app.py modified
[2023-07-02 13:31:48 +0700] [4620] [INFO] Worker exiting (pid: 4620)
[2023-07-02 13:31:48 +0700] [4661] [INFO] Booting worker with pid: 4661
[2023-07-02 13:31:49 +0700] [4661] [ERROR] Exception in worker process
Traceback (most recent call last):
  File "/usr/lib/python3/dist-packages/gunicorn/arbiter.py", line 589, in spawn_worker
    worker.init_process()
  File "/usr/lib/python3/dist-packages/gunicorn/workers/base.py", line 134, in init_process
    self.load_wsgi()
  File "/usr/lib/python3/dist-packages/gunicorn/workers/base.py", line 146, in load_wsgi
    self.wsgi = self.app.wsgi()
  File "/usr/lib/python3/dist-packages/gunicorn/app/base.py", line 67, in wsgi
    self.callable = self.load()
  File "/usr/lib/python3/dist-packages/gunicorn/app/wsgiapp.py", line 58, in load
    return self.load_wsgiapp()
  File "/usr/lib/python3/dist-packages/gunicorn/app/wsgiapp.py", line 48, in load_wsgiapp
    return util.import_app(self.app_uri)
  File "/usr/lib/python3/dist-packages/gunicorn/util.py", line 384, in import_app
    mod = importlib.import_module(module)
  File "/usr/lib/python3.10/importlib/__init__.py", line 126, in import_module
    return _bootstrap._gcd_import(name[level:], package, level)
  File "<frozen importlib._bootstrap>", line 1050, in _gcd_import
  File "<frozen importlib._bootstrap>", line 1027, in _find_and_load
  File "<frozen importlib._bootstrap>", line 1006, in _find_and_load_unlocked
  File "<frozen importlib._bootstrap>", line 688, in _load_unlocked
  File "<frozen importlib._bootstrap_external>", line 883, in exec_module
  File "<frozen importlib._bootstrap>", line 241, in _call_with_frames_removed
  File "/home/ultiv/Code/DevC/app.py", line 4, in <module>
    from balance import balance
  File "/home/ultiv/Code/DevC/balance.py", line 2, in <module>
    from lol import *
ModuleNotFoundError: No module named 'lol'
[2023-07-02 13:31:49 +0700] [4661] [INFO] Worker exiting (pid: 4661)
[2023-07-02 13:31:49 +0700] [4082] [INFO] Shutting down: Master
[2023-07-02 13:31:49 +0700] [4082] [INFO] Reason: Worker failed to boot.
[2023-07-02 13:44:49 +0700] [4812] [INFO] Starting gunicorn 20.1.0
[2023-07-02 13:44:49 +0700] [4812] [INFO] Listening at: unix:/run/devc.sock (4812)
[2023-07-02 13:44:49 +0700] [4812] [INFO] Using worker: sync
[2023-07-02 13:44:49 +0700] [4813] [INFO] Booting worker with pid: 4813
[2023-07-02 13:44:49 +0700] [4813] [ERROR] Exception in worker process
Traceback (most recent call last):
  File "/usr/lib/python3/dist-packages/gunicorn/arbiter.py", line 589, in spawn_worker
    worker.init_process()
  File "/usr/lib/python3/dist-packages/gunicorn/workers/base.py", line 134, in init_process
    self.load_wsgi()
  File "/usr/lib/python3/dist-packages/gunicorn/workers/base.py", line 146, in load_wsgi
    self.wsgi = self.app.wsgi()
  File "/usr/lib/python3/dist-packages/gunicorn/app/base.py", line 67, in wsgi
    self.callable = self.load()
  File "/usr/lib/python3/dist-packages/gunicorn/app/wsgiapp.py", line 58, in load
    return self.load_wsgiapp()
  File "/usr/lib/python3/dist-packages/gunicorn/app/wsgiapp.py", line 48, in load_wsgiapp
    return util.import_app(self.app_uri)
  File "/usr/lib/python3/dist-packages/gunicorn/util.py", line 384, in import_app
    mod = importlib.import_module(module)
  File "/usr/lib/python3.10/importlib/__init__.py", line 126, in import_module
    return _bootstrap._gcd_import(name[level:], package, level)
  File "<frozen importlib._bootstrap>", line 1050, in _gcd_import
  File "<frozen importlib._bootstrap>", line 1027, in _find_and_load
  File "<frozen importlib._bootstrap>", line 1006, in _find_and_load_unlocked
  File "<frozen importlib._bootstrap>", line 688, in _load_unlocked
  File "<frozen importlib._bootstrap_external>", line 883, in exec_module
  File "<frozen importlib._bootstrap>", line 241, in _call_with_frames_removed
  File "/home/ultiv/Code/DevC/app.py", line 4, in <module>
    from balance import balance
  File "/home/ultiv/Code/DevC/balance.py", line 2, in <module>
    from lol import *
ModuleNotFoundError: No module named 'lol'
[2023-07-02 13:44:49 +0700] [4813] [INFO] Worker exiting (pid: 4813)
[2023-07-02 13:44:49 +0700] [4812] [INFO] Shutting down: Master
[2023-07-02 13:44:49 +0700] [4812] [INFO] Reason: Worker failed to boot.
[2023-07-02 13:44:49 +0700] [4821] [INFO] Starting gunicorn 20.1.0
[2023-07-02 13:44:49 +0700] [4821] [INFO] Listening at: unix:/run/devc.sock (4821)
[2023-07-02 13:44:49 +0700] [4821] [INFO] Using worker: sync
[2023-07-02 13:44:49 +0700] [4822] [INFO] Booting worker with pid: 4822
[2023-07-02 13:44:50 +0700] [4822] [ERROR] Exception in worker process
Traceback (most recent call last):
  File "/usr/lib/python3/dist-packages/gunicorn/arbiter.py", line 589, in spawn_worker
    worker.init_process()
  File "/usr/lib/python3/dist-packages/gunicorn/workers/base.py", line 134, in init_process
    self.load_wsgi()
  File "/usr/lib/python3/dist-packages/gunicorn/workers/base.py", line 146, in load_wsgi
    self.wsgi = self.app.wsgi()
  File "/usr/lib/python3/dist-packages/gunicorn/app/base.py", line 67, in wsgi
    self.callable = self.load()
  File "/usr/lib/python3/dist-packages/gunicorn/app/wsgiapp.py", line 58, in load
    return self.load_wsgiapp()
  File "/usr/lib/python3/dist-packages/gunicorn/app/wsgiapp.py", line 48, in load_wsgiapp
    return util.import_app(self.app_uri)
  File "/usr/lib/python3/dist-packages/gunicorn/util.py", line 384, in import_app
    mod = importlib.import_module(module)
  File "/usr/lib/python3.10/importlib/__init__.py", line 126, in import_module
    return _bootstrap._gcd_import(name[level:], package, level)
  File "<frozen importlib._bootstrap>", line 1050, in _gcd_import
  File "<frozen importlib._bootstrap>", line 1027, in _find_and_load
  File "<frozen importlib._bootstrap>", line 1006, in _find_and_load_unlocked
  File "<frozen importlib._bootstrap>", line 688, in _load_unlocked
  File "<frozen importlib._bootstrap_external>", line 883, in exec_module
  File "<frozen importlib._bootstrap>", line 241, in _call_with_frames_removed
  File "/home/ultiv/Code/DevC/app.py", line 4, in <module>
    from balance import balance
  File "/home/ultiv/Code/DevC/balance.py", line 2, in <module>
    from lol import *
ModuleNotFoundError: No module named 'lol'
[2023-07-02 13:44:50 +0700] [4822] [INFO] Worker exiting (pid: 4822)
[2023-07-02 13:44:50 +0700] [4821] [INFO] Shutting down: Master
[2023-07-02 13:44:50 +0700] [4821] [INFO] Reason: Worker failed to boot.
[2023-07-02 13:44:50 +0700] [4829] [INFO] Starting gunicorn 20.1.0
[2023-07-02 13:44:50 +0700] [4829] [INFO] Listening at: unix:/run/devc.sock (4829)
[2023-07-02 13:44:50 +0700] [4829] [INFO] Using worker: sync
[2023-07-02 13:44:50 +0700] [4831] [INFO] Booting worker with pid: 4831
[2023-07-02 13:44:50 +0700] [4831] [ERROR] Exception in worker process
Traceback (most recent call last):
  File "/usr/lib/python3/dist-packages/gunicorn/arbiter.py", line 589, in spawn_worker
    worker.init_process()
  File "/usr/lib/python3/dist-packages/gunicorn/workers/base.py", line 134, in init_process
    self.load_wsgi()
  File "/usr/lib/python3/dist-packages/gunicorn/workers/base.py", line 146, in load_wsgi
    self.wsgi = self.app.wsgi()
  File "/usr/lib/python3/dist-packages/gunicorn/app/base.py", line 67, in wsgi
    self.callable = self.load()
  File "/usr/lib/python3/dist-packages/gunicorn/app/wsgiapp.py", line 58, in load
    return self.load_wsgiapp()
  File "/usr/lib/python3/dist-packages/gunicorn/app/wsgiapp.py", line 48, in load_wsgiapp
    return util.import_app(self.app_uri)
  File "/usr/lib/python3/dist-packages/gunicorn/util.py", line 384, in import_app
    mod = importlib.import_module(module)
  File "/usr/lib/python3.10/importlib/__init__.py", line 126, in import_module
    return _bootstrap._gcd_import(name[level:], package, level)
  File "<frozen importlib._bootstrap>", line 1050, in _gcd_import
  File "<frozen importlib._bootstrap>", line 1027, in _find_and_load
  File "<frozen importlib._bootstrap>", line 1006, in _find_and_load_unlocked
  File "<frozen importlib._bootstrap>", line 688, in _load_unlocked
  File "<frozen importlib._bootstrap_external>", line 883, in exec_module
  File "<frozen importlib._bootstrap>", line 241, in _call_with_frames_removed
  File "/home/ultiv/Code/DevC/app.py", line 4, in <module>
    from balance import balance
  File "/home/ultiv/Code/DevC/balance.py", line 2, in <module>
    from lol import *
ModuleNotFoundError: No module named 'lol'
[2023-07-02 13:44:50 +0700] [4831] [INFO] Worker exiting (pid: 4831)
[2023-07-02 13:44:51 +0700] [4829] [INFO] Shutting down: Master
[2023-07-02 13:44:51 +0700] [4829] [INFO] Reason: Worker failed to boot.
[2023-07-02 13:44:51 +0700] [4839] [INFO] Starting gunicorn 20.1.0
[2023-07-02 13:44:51 +0700] [4839] [INFO] Listening at: unix:/run/devc.sock (4839)
[2023-07-02 13:44:51 +0700] [4839] [INFO] Using worker: sync
[2023-07-02 13:44:51 +0700] [4841] [INFO] Booting worker with pid: 4841
[2023-07-02 13:44:51 +0700] [4841] [ERROR] Exception in worker process
Traceback (most recent call last):
  File "/usr/lib/python3/dist-packages/gunicorn/arbiter.py", line 589, in spawn_worker
    worker.init_process()
  File "/usr/lib/python3/dist-packages/gunicorn/workers/base.py", line 134, in init_process
    self.load_wsgi()
  File "/usr/lib/python3/dist-packages/gunicorn/workers/base.py", line 146, in load_wsgi
    self.wsgi = self.app.wsgi()
  File "/usr/lib/python3/dist-packages/gunicorn/app/base.py", line 67, in wsgi
    self.callable = self.load()
  File "/usr/lib/python3/dist-packages/gunicorn/app/wsgiapp.py", line 58, in load
    return self.load_wsgiapp()
  File "/usr/lib/python3/dist-packages/gunicorn/app/wsgiapp.py", line 48, in load_wsgiapp
    return util.import_app(self.app_uri)
  File "/usr/lib/python3/dist-packages/gunicorn/util.py", line 384, in import_app
    mod = importlib.import_module(module)
  File "/usr/lib/python3.10/importlib/__init__.py", line 126, in import_module
    return _bootstrap._gcd_import(name[level:], package, level)
  File "<frozen importlib._bootstrap>", line 1050, in _gcd_import
  File "<frozen importlib._bootstrap>", line 1027, in _find_and_load
  File "<frozen importlib._bootstrap>", line 1006, in _find_and_load_unlocked
  File "<frozen importlib._bootstrap>", line 688, in _load_unlocked
  File "<frozen importlib._bootstrap_external>", line 883, in exec_module
  File "<frozen importlib._bootstrap>", line 241, in _call_with_frames_removed
  File "/home/ultiv/Code/DevC/app.py", line 4, in <module>
    from balance import balance
  File "/home/ultiv/Code/DevC/balance.py", line 2, in <module>
    from lol import *
ModuleNotFoundError: No module named 'lol'
[2023-07-02 13:44:51 +0700] [4841] [INFO] Worker exiting (pid: 4841)
[2023-07-02 13:44:52 +0700] [4839] [INFO] Shutting down: Master
[2023-07-02 13:44:52 +0700] [4839] [INFO] Reason: Worker failed to boot.
[2023-07-02 13:44:52 +0700] [4850] [INFO] Starting gunicorn 20.1.0
[2023-07-02 13:44:52 +0700] [4850] [INFO] Listening at: unix:/run/devc.sock (4850)
[2023-07-02 13:44:52 +0700] [4850] [INFO] Using worker: sync
[2023-07-02 13:44:52 +0700] [4851] [INFO] Booting worker with pid: 4851
[2023-07-02 13:44:52 +0700] [4851] [ERROR] Exception in worker process
Traceback (most recent call last):
  File "/usr/lib/python3/dist-packages/gunicorn/arbiter.py", line 589, in spawn_worker
    worker.init_process()
  File "/usr/lib/python3/dist-packages/gunicorn/workers/base.py", line 134, in init_process
    self.load_wsgi()
  File "/usr/lib/python3/dist-packages/gunicorn/workers/base.py", line 146, in load_wsgi
    self.wsgi = self.app.wsgi()
  File "/usr/lib/python3/dist-packages/gunicorn/app/base.py", line 67, in wsgi
    self.callable = self.load()
  File "/usr/lib/python3/dist-packages/gunicorn/app/wsgiapp.py", line 58, in load
    return self.load_wsgiapp()
  File "/usr/lib/python3/dist-packages/gunicorn/app/wsgiapp.py", line 48, in load_wsgiapp
    return util.import_app(self.app_uri)
  File "/usr/lib/python3/dist-packages/gunicorn/util.py", line 384, in import_app
    mod = importlib.import_module(module)
  File "/usr/lib/python3.10/importlib/__init__.py", line 126, in import_module
    return _bootstrap._gcd_import(name[level:], package, level)
  File "<frozen importlib._bootstrap>", line 1050, in _gcd_import
  File "<frozen importlib._bootstrap>", line 1027, in _find_and_load
  File "<frozen importlib._bootstrap>", line 1006, in _find_and_load_unlocked
  File "<frozen importlib._bootstrap>", line 688, in _load_unlocked
  File "<frozen importlib._bootstrap_external>", line 883, in exec_module
  File "<frozen importlib._bootstrap>", line 241, in _call_with_frames_removed
  File "/home/ultiv/Code/DevC/app.py", line 4, in <module>
    from balance import balance
  File "/home/ultiv/Code/DevC/balance.py", line 2, in <module>
    from lol import *
ModuleNotFoundError: No module named 'lol'
[2023-07-02 13:44:52 +0700] [4851] [INFO] Worker exiting (pid: 4851)
[2023-07-02 13:44:53 +0700] [4850] [INFO] Shutting down: Master
[2023-07-02 13:44:53 +0700] [4850] [INFO] Reason: Worker failed to boot.
[2023-07-02 13:45:37 +0700] [4903] [INFO] Starting gunicorn 20.1.0
[2023-07-02 13:45:37 +0700] [4903] [INFO] Listening at: unix:/run/devc.sock (4903)
[2023-07-02 13:45:37 +0700] [4903] [INFO] Using worker: sync
[2023-07-02 13:45:37 +0700] [4904] [INFO] Booting worker with pid: 4904
[2023-07-02 13:45:37 +0700] [4904] [ERROR] Exception in worker process
Traceback (most recent call last):
  File "/usr/lib/python3/dist-packages/gunicorn/arbiter.py", line 589, in spawn_worker
    worker.init_process()
  File "/usr/lib/python3/dist-packages/gunicorn/workers/base.py", line 134, in init_process
    self.load_wsgi()
  File "/usr/lib/python3/dist-packages/gunicorn/workers/base.py", line 146, in load_wsgi
    self.wsgi = self.app.wsgi()
  File "/usr/lib/python3/dist-packages/gunicorn/app/base.py", line 67, in wsgi
    self.callable = self.load()
  File "/usr/lib/python3/dist-packages/gunicorn/app/wsgiapp.py", line 58, in load
    return self.load_wsgiapp()
  File "/usr/lib/python3/dist-packages/gunicorn/app/wsgiapp.py", line 48, in load_wsgiapp
    return util.import_app(self.app_uri)
  File "/usr/lib/python3/dist-packages/gunicorn/util.py", line 384, in import_app
    mod = importlib.import_module(module)
  File "/usr/lib/python3.10/importlib/__init__.py", line 126, in import_module
    return _bootstrap._gcd_import(name[level:], package, level)
  File "<frozen importlib._bootstrap>", line 1050, in _gcd_import
  File "<frozen importlib._bootstrap>", line 1027, in _find_and_load
  File "<frozen importlib._bootstrap>", line 1006, in _find_and_load_unlocked
  File "<frozen importlib._bootstrap>", line 688, in _load_unlocked
  File "<frozen importlib._bootstrap_external>", line 883, in exec_module
  File "<frozen importlib._bootstrap>", line 241, in _call_with_frames_removed
  File "/home/ultiv/Code/DevC/app.py", line 4, in <module>
    from balance import balance
  File "/home/ultiv/Code/DevC/balance.py", line 2, in <module>
    from lol import *
ModuleNotFoundError: No module named 'lol'
[2023-07-02 13:45:37 +0700] [4904] [INFO] Worker exiting (pid: 4904)
[2023-07-02 13:45:38 +0700] [4903] [INFO] Shutting down: Master
[2023-07-02 13:45:38 +0700] [4903] [INFO] Reason: Worker failed to boot.
[2023-07-02 13:45:41 +0700] [4912] [INFO] Starting gunicorn 20.1.0
[2023-07-02 13:45:41 +0700] [4912] [INFO] Listening at: unix:/run/devc.sock (4912)
[2023-07-02 13:45:41 +0700] [4912] [INFO] Using worker: sync
[2023-07-02 13:45:41 +0700] [4913] [INFO] Booting worker with pid: 4913
[2023-07-02 13:45:41 +0700] [4913] [ERROR] Exception in worker process
Traceback (most recent call last):
  File "/usr/lib/python3/dist-packages/gunicorn/arbiter.py", line 589, in spawn_worker
    worker.init_process()
  File "/usr/lib/python3/dist-packages/gunicorn/workers/base.py", line 134, in init_process
    self.load_wsgi()
  File "/usr/lib/python3/dist-packages/gunicorn/workers/base.py", line 146, in load_wsgi
    self.wsgi = self.app.wsgi()
  File "/usr/lib/python3/dist-packages/gunicorn/app/base.py", line 67, in wsgi
    self.callable = self.load()
  File "/usr/lib/python3/dist-packages/gunicorn/app/wsgiapp.py", line 58, in load
    return self.load_wsgiapp()
  File "/usr/lib/python3/dist-packages/gunicorn/app/wsgiapp.py", line 48, in load_wsgiapp
    return util.import_app(self.app_uri)
  File "/usr/lib/python3/dist-packages/gunicorn/util.py", line 384, in import_app
    mod = importlib.import_module(module)
  File "/usr/lib/python3.10/importlib/__init__.py", line 126, in import_module
    return _bootstrap._gcd_import(name[level:], package, level)
  File "<frozen importlib._bootstrap>", line 1050, in _gcd_import
  File "<frozen importlib._bootstrap>", line 1027, in _find_and_load
  File "<frozen importlib._bootstrap>", line 1006, in _find_and_load_unlocked
  File "<frozen importlib._bootstrap>", line 688, in _load_unlocked
  File "<frozen importlib._bootstrap_external>", line 883, in exec_module
  File "<frozen importlib._bootstrap>", line 241, in _call_with_frames_removed
  File "/home/ultiv/Code/DevC/app.py", line 4, in <module>
    from balance import balance
  File "/home/ultiv/Code/DevC/balance.py", line 2, in <module>
    from lol import *
ModuleNotFoundError: No module named 'lol'
[2023-07-02 13:45:41 +0700] [4913] [INFO] Worker exiting (pid: 4913)
[2023-07-02 13:45:41 +0700] [4912] [INFO] Shutting down: Master
[2023-07-02 13:45:41 +0700] [4912] [INFO] Reason: Worker failed to boot.
[2023-07-02 13:45:41 +0700] [4921] [INFO] Starting gunicorn 20.1.0
[2023-07-02 13:45:41 +0700] [4921] [INFO] Listening at: unix:/run/devc.sock (4921)
[2023-07-02 13:45:41 +0700] [4921] [INFO] Using worker: sync
[2023-07-02 13:45:41 +0700] [4922] [INFO] Booting worker with pid: 4922
[2023-07-02 13:45:42 +0700] [4922] [ERROR] Exception in worker process
Traceback (most recent call last):
  File "/usr/lib/python3/dist-packages/gunicorn/arbiter.py", line 589, in spawn_worker
    worker.init_process()
  File "/usr/lib/python3/dist-packages/gunicorn/workers/base.py", line 134, in init_process
    self.load_wsgi()
  File "/usr/lib/python3/dist-packages/gunicorn/workers/base.py", line 146, in load_wsgi
    self.wsgi = self.app.wsgi()
  File "/usr/lib/python3/dist-packages/gunicorn/app/base.py", line 67, in wsgi
    self.callable = self.load()
  File "/usr/lib/python3/dist-packages/gunicorn/app/wsgiapp.py", line 58, in load
    return self.load_wsgiapp()
  File "/usr/lib/python3/dist-packages/gunicorn/app/wsgiapp.py", line 48, in load_wsgiapp
    return util.import_app(self.app_uri)
  File "/usr/lib/python3/dist-packages/gunicorn/util.py", line 384, in import_app
    mod = importlib.import_module(module)
  File "/usr/lib/python3.10/importlib/__init__.py", line 126, in import_module
    return _bootstrap._gcd_import(name[level:], package, level)
  File "<frozen importlib._bootstrap>", line 1050, in _gcd_import
  File "<frozen importlib._bootstrap>", line 1027, in _find_and_load
  File "<frozen importlib._bootstrap>", line 1006, in _find_and_load_unlocked
  File "<frozen importlib._bootstrap>", line 688, in _load_unlocked
  File "<frozen importlib._bootstrap_external>", line 883, in exec_module
  File "<frozen importlib._bootstrap>", line 241, in _call_with_frames_removed
  File "/home/ultiv/Code/DevC/app.py", line 4, in <module>
    from balance import balance
  File "/home/ultiv/Code/DevC/balance.py", line 2, in <module>
    from lol import *
ModuleNotFoundError: No module named 'lol'
[2023-07-02 13:45:42 +0700] [4922] [INFO] Worker exiting (pid: 4922)
[2023-07-02 13:45:42 +0700] [4921] [INFO] Shutting down: Master
[2023-07-02 13:45:42 +0700] [4921] [INFO] Reason: Worker failed to boot.
[2023-07-02 13:45:42 +0700] [4929] [INFO] Starting gunicorn 20.1.0
[2023-07-02 13:45:42 +0700] [4929] [INFO] Listening at: unix:/run/devc.sock (4929)
[2023-07-02 13:45:42 +0700] [4929] [INFO] Using worker: sync
[2023-07-02 13:45:42 +0700] [4930] [INFO] Booting worker with pid: 4930
[2023-07-02 13:45:43 +0700] [4930] [ERROR] Exception in worker process
Traceback (most recent call last):
  File "/usr/lib/python3/dist-packages/gunicorn/arbiter.py", line 589, in spawn_worker
    worker.init_process()
  File "/usr/lib/python3/dist-packages/gunicorn/workers/base.py", line 134, in init_process
    self.load_wsgi()
  File "/usr/lib/python3/dist-packages/gunicorn/workers/base.py", line 146, in load_wsgi
    self.wsgi = self.app.wsgi()
  File "/usr/lib/python3/dist-packages/gunicorn/app/base.py", line 67, in wsgi
    self.callable = self.load()
  File "/usr/lib/python3/dist-packages/gunicorn/app/wsgiapp.py", line 58, in load
    return self.load_wsgiapp()
  File "/usr/lib/python3/dist-packages/gunicorn/app/wsgiapp.py", line 48, in load_wsgiapp
    return util.import_app(self.app_uri)
  File "/usr/lib/python3/dist-packages/gunicorn/util.py", line 384, in import_app
    mod = importlib.import_module(module)
  File "/usr/lib/python3.10/importlib/__init__.py", line 126, in import_module
    return _bootstrap._gcd_import(name[level:], package, level)
  File "<frozen importlib._bootstrap>", line 1050, in _gcd_import
  File "<frozen importlib._bootstrap>", line 1027, in _find_and_load
  File "<frozen importlib._bootstrap>", line 1006, in _find_and_load_unlocked
  File "<frozen importlib._bootstrap>", line 688, in _load_unlocked
  File "<frozen importlib._bootstrap_external>", line 883, in exec_module
  File "<frozen importlib._bootstrap>", line 241, in _call_with_frames_removed
  File "/home/ultiv/Code/DevC/app.py", line 4, in <module>
    from balance import balance
  File "/home/ultiv/Code/DevC/balance.py", line 2, in <module>
    from lol import *
ModuleNotFoundError: No module named 'lol'
[2023-07-02 13:45:43 +0700] [4930] [INFO] Worker exiting (pid: 4930)
[2023-07-02 13:45:43 +0700] [4929] [INFO] Shutting down: Master
[2023-07-02 13:45:43 +0700] [4929] [INFO] Reason: Worker failed to boot.
[2023-07-02 13:45:43 +0700] [4936] [INFO] Starting gunicorn 20.1.0
[2023-07-02 13:45:43 +0700] [4936] [INFO] Listening at: unix:/run/devc.sock (4936)
[2023-07-02 13:45:43 +0700] [4936] [INFO] Using worker: sync
[2023-07-02 13:45:43 +0700] [4938] [INFO] Booting worker with pid: 4938
[2023-07-02 13:45:43 +0700] [4938] [ERROR] Exception in worker process
Traceback (most recent call last):
  File "/usr/lib/python3/dist-packages/gunicorn/arbiter.py", line 589, in spawn_worker
    worker.init_process()
  File "/usr/lib/python3/dist-packages/gunicorn/workers/base.py", line 134, in init_process
    self.load_wsgi()
  File "/usr/lib/python3/dist-packages/gunicorn/workers/base.py", line 146, in load_wsgi
    self.wsgi = self.app.wsgi()
  File "/usr/lib/python3/dist-packages/gunicorn/app/base.py", line 67, in wsgi
    self.callable = self.load()
  File "/usr/lib/python3/dist-packages/gunicorn/app/wsgiapp.py", line 58, in load
    return self.load_wsgiapp()
  File "/usr/lib/python3/dist-packages/gunicorn/app/wsgiapp.py", line 48, in load_wsgiapp
    return util.import_app(self.app_uri)
  File "/usr/lib/python3/dist-packages/gunicorn/util.py", line 384, in import_app
    mod = importlib.import_module(module)
  File "/usr/lib/python3.10/importlib/__init__.py", line 126, in import_module
    return _bootstrap._gcd_import(name[level:], package, level)
  File "<frozen importlib._bootstrap>", line 1050, in _gcd_import
  File "<frozen importlib._bootstrap>", line 1027, in _find_and_load
  File "<frozen importlib._bootstrap>", line 1006, in _find_and_load_unlocked
  File "<frozen importlib._bootstrap>", line 688, in _load_unlocked
  File "<frozen importlib._bootstrap_external>", line 883, in exec_module
  File "<frozen importlib._bootstrap>", line 241, in _call_with_frames_removed
  File "/home/ultiv/Code/DevC/app.py", line 4, in <module>
    from balance import balance
  File "/home/ultiv/Code/DevC/balance.py", line 2, in <module>
    from lol import *
ModuleNotFoundError: No module named 'lol'
[2023-07-02 13:45:43 +0700] [4938] [INFO] Worker exiting (pid: 4938)
[2023-07-02 13:45:44 +0700] [4936] [INFO] Shutting down: Master
[2023-07-02 13:45:44 +0700] [4936] [INFO] Reason: Worker failed to boot.
[2023-07-02 13:47:19 +0700] [4979] [INFO] Starting gunicorn 20.1.0
[2023-07-02 13:47:19 +0700] [4979] [INFO] Listening at: unix:/run/devc.sock (4979)
[2023-07-02 13:47:19 +0700] [4979] [INFO] Using worker: sync
[2023-07-02 13:47:19 +0700] [4980] [INFO] Booting worker with pid: 4980
[2023-07-02 13:47:43,320] ERROR in app: Exception on /tournaments [GET]
Traceback (most recent call last):
  File "/usr/lib/python3/dist-packages/flask/app.py", line 2070, in wsgi_app
    response = self.full_dispatch_request()
  File "/usr/lib/python3/dist-packages/flask/app.py", line 1515, in full_dispatch_request
    rv = self.handle_user_exception(e)
  File "/usr/lib/python3/dist-packages/flask/app.py", line 1513, in full_dispatch_request
    rv = self.dispatch_request()
  File "/usr/lib/python3/dist-packages/flask/app.py", line 1499, in dispatch_request
    return self.ensure_sync(self.view_functions[rule.endpoint])(**req.view_args)
  File "/home/ultiv/Code/DevC/app.py", line 28, in tournaments
    return render_template("tournaments.html", items=get_all('tournaments'), labels=tournament)
  File "/usr/lib/python3/dist-packages/flask/templating.py", line 148, in render_template
    ctx.app.jinja_env.get_or_select_template(template_name_or_list),
  File "/usr/lib/python3/dist-packages/jinja2/environment.py", line 1068, in get_or_select_template
    return self.get_template(template_name_or_list, parent, globals)
  File "/usr/lib/python3/dist-packages/jinja2/environment.py", line 997, in get_template
    return self._load_template(name, globals)
  File "/usr/lib/python3/dist-packages/jinja2/environment.py", line 958, in _load_template
    template = self.loader.load(self, name, self.make_globals(globals))
  File "/usr/lib/python3/dist-packages/jinja2/loaders.py", line 137, in load
    code = environment.compile(source, name, filename)
  File "/usr/lib/python3/dist-packages/jinja2/environment.py", line 757, in compile
    self.handle_exception(source=source_hint)
  File "/usr/lib/python3/dist-packages/jinja2/environment.py", line 925, in handle_exception
    raise rewrite_traceback_stack(source=source)
  File "/home/ultiv/Code/DevC/templates/tournaments.html", line 5, in template
    {% extends 'list.html' %}
jinja2.exceptions.TemplateAssertionError: cannot use extend from a non top-level scope
[2023-07-02 13:49:29 +0700] [4979] [INFO] Handling signal: term
[2023-07-02 13:49:29 +0700] [4980] [INFO] Worker exiting (pid: 4980)
[2023-07-02 13:49:29 +0700] [4979] [INFO] Shutting down: Master
[2023-07-02 13:49:29 +0700] [5336] [INFO] Starting gunicorn 20.1.0
[2023-07-02 13:49:29 +0700] [5336] [INFO] Listening at: unix:/run/devc.sock (5336)
[2023-07-02 13:49:29 +0700] [5336] [INFO] Using worker: sync
[2023-07-02 13:49:29 +0700] [5337] [INFO] Booting worker with pid: 5337
[2023-07-02 13:49:32,205] ERROR in app: Exception on /tournaments [GET]
Traceback (most recent call last):
  File "/usr/lib/python3/dist-packages/flask/app.py", line 2070, in wsgi_app
    response = self.full_dispatch_request()
  File "/usr/lib/python3/dist-packages/flask/app.py", line 1515, in full_dispatch_request
    rv = self.handle_user_exception(e)
  File "/usr/lib/python3/dist-packages/flask/app.py", line 1513, in full_dispatch_request
    rv = self.dispatch_request()
  File "/usr/lib/python3/dist-packages/flask/app.py", line 1499, in dispatch_request
    return self.ensure_sync(self.view_functions[rule.endpoint])(**req.view_args)
  File "/home/ultiv/Code/DevC/app.py", line 28, in tournaments
    return render_template("tournaments.html", items=get_all('tournaments'), labels=tournament)
  File "/usr/lib/python3/dist-packages/flask/templating.py", line 147, in render_template
    return _render(
  File "/usr/lib/python3/dist-packages/flask/templating.py", line 128, in _render
    rv = template.render(context)
  File "/usr/lib/python3/dist-packages/jinja2/environment.py", line 1291, in render
    self.environment.handle_exception()
  File "/usr/lib/python3/dist-packages/jinja2/environment.py", line 925, in handle_exception
    raise rewrite_traceback_stack(source=source)
  File "/home/ultiv/Code/DevC/templates/tournaments.html", line 1, in top-level template code
    {%extends 'base.html'%}
  File "/home/ultiv/Code/DevC/templates/base.html", line 14, in top-level template code
    {% block body %}{% endblock %}
  File "/home/ultiv/Code/DevC/templates/tournaments.html", line 5, in block 'body'
    {% include 'list.html' %}
  File "/home/ultiv/Code/DevC/templates/list.html", line 12, in top-level template code
    <td>{{tournament[field]}}</td>
  File "/usr/lib/python3/dist-packages/jinja2/environment.py", line 455, in getitem
    return obj[argument]
jinja2.exceptions.UndefinedError: 'tournament' is undefined
[2023-07-02 13:50:23 +0700] [5336] [INFO] Handling signal: term
[2023-07-02 13:50:23 +0700] [5337] [INFO] Worker exiting (pid: 5337)
[2023-07-02 13:50:23 +0700] [5336] [INFO] Shutting down: Master
[2023-07-02 13:50:23 +0700] [5365] [INFO] Starting gunicorn 20.1.0
[2023-07-02 13:50:23 +0700] [5365] [INFO] Listening at: unix:/run/devc.sock (5365)
[2023-07-02 13:50:23 +0700] [5365] [INFO] Using worker: sync
[2023-07-02 13:50:23 +0700] [5366] [INFO] Booting worker with pid: 5366
[2023-07-02 13:51:35 +0700] [5366] [INFO] Worker reloading: /home/ultiv/Code/DevC/lol_metadata.py modified
[2023-07-02 13:51:35 +0700] [5366] [INFO] Worker exiting (pid: 5366)
[2023-07-02 13:51:35 +0700] [5410] [INFO] Booting worker with pid: 5410
[2023-07-02 13:53:58 +0700] [5410] [INFO] Worker reloading: /home/ultiv/Code/DevC/app.py modified
[2023-07-02 13:53:58 +0700] [5410] [INFO] Worker exiting (pid: 5410)
[2023-07-02 13:53:58 +0700] [5449] [INFO] Booting worker with pid: 5449
[2023-07-02 13:54:01,628] ERROR in app: Exception on /players [GET]
Traceback (most recent call last):
  File "/usr/lib/python3/dist-packages/flask/app.py", line 2070, in wsgi_app
    response = self.full_dispatch_request()
  File "/usr/lib/python3/dist-packages/flask/app.py", line 1515, in full_dispatch_request
    rv = self.handle_user_exception(e)
  File "/usr/lib/python3/dist-packages/flask/app.py", line 1513, in full_dispatch_request
    rv = self.dispatch_request()
  File "/usr/lib/python3/dist-packages/flask/app.py", line 1499, in dispatch_request
    return self.ensure_sync(self.view_functions[rule.endpoint])(**req.view_args)
  File "/home/ultiv/Code/DevC/app.py", line 36, in get_players
    players["ranks"] += " " + players["div"]
TypeError: list indices must be integers or slices, not str
[2023-07-02 13:54:50 +0700] [5449] [INFO] Worker reloading: /home/ultiv/Code/DevC/app.py modified
[2023-07-02 13:54:50 +0700] [5449] [INFO] Worker exiting (pid: 5449)
[2023-07-02 13:54:50 +0700] [5471] [INFO] Booting worker with pid: 5471
[2023-07-02 13:54:52,059] ERROR in app: Exception on /players [GET]
Traceback (most recent call last):
  File "/usr/lib/python3/dist-packages/flask/app.py", line 2070, in wsgi_app
    response = self.full_dispatch_request()
  File "/usr/lib/python3/dist-packages/flask/app.py", line 1515, in full_dispatch_request
    rv = self.handle_user_exception(e)
  File "/usr/lib/python3/dist-packages/flask/app.py", line 1513, in full_dispatch_request
    rv = self.dispatch_request()
  File "/usr/lib/python3/dist-packages/flask/app.py", line 1499, in dispatch_request
    return self.ensure_sync(self.view_functions[rule.endpoint])(**req.view_args)
  File "/home/ultiv/Code/DevC/app.py", line 36, in get_players
    players["ranks"] += " " + str(players["div"])
TypeError: list indices must be integers or slices, not str
[2023-07-02 13:54:55,304] ERROR in app: Exception on /players [GET]
Traceback (most recent call last):
  File "/usr/lib/python3/dist-packages/flask/app.py", line 2070, in wsgi_app
    response = self.full_dispatch_request()
  File "/usr/lib/python3/dist-packages/flask/app.py", line 1515, in full_dispatch_request
    rv = self.handle_user_exception(e)
  File "/usr/lib/python3/dist-packages/flask/app.py", line 1513, in full_dispatch_request
    rv = self.dispatch_request()
  File "/usr/lib/python3/dist-packages/flask/app.py", line 1499, in dispatch_request
    return self.ensure_sync(self.view_functions[rule.endpoint])(**req.view_args)
  File "/home/ultiv/Code/DevC/app.py", line 36, in get_players
    players["ranks"] += " " + str(players["div"])
TypeError: list indices must be integers or slices, not str
[2023-07-02 13:56:03 +0700] [5471] [INFO] Worker reloading: /home/ultiv/Code/DevC/app.py modified
[2023-07-02 13:56:03 +0700] [5471] [INFO] Worker exiting (pid: 5471)
[2023-07-02 13:56:03 +0700] [5498] [INFO] Booting worker with pid: 5498
[2023-07-02 13:56:16 +0700] [5498] [INFO] Worker reloading: /home/ultiv/Code/DevC/app.py modified
[2023-07-02 13:56:16 +0700] [5498] [INFO] Worker exiting (pid: 5498)
[2023-07-02 13:56:17 +0700] [5507] [INFO] Booting worker with pid: 5507
[2023-07-02 13:56:18,514] ERROR in app: Exception on /players [GET]
Traceback (most recent call last):
  File "/usr/lib/python3/dist-packages/flask/app.py", line 2070, in wsgi_app
    response = self.full_dispatch_request()
  File "/usr/lib/python3/dist-packages/flask/app.py", line 1515, in full_dispatch_request
    rv = self.handle_user_exception(e)
  File "/usr/lib/python3/dist-packages/flask/app.py", line 1513, in full_dispatch_request
    rv = self.dispatch_request()
  File "/usr/lib/python3/dist-packages/flask/app.py", line 1499, in dispatch_request
    return self.ensure_sync(self.view_functions[rule.endpoint])(**req.view_args)
  File "/home/ultiv/Code/DevC/app.py", line 37, in get_players
    players["ranks"] += " " + players["div"]
TypeError: list indices must be integers or slices, not str
[2023-07-02 13:56:51 +0700] [5507] [INFO] Worker reloading: /home/ultiv/Code/DevC/app.py modified
[2023-07-02 13:56:51 +0700] [5507] [INFO] Worker exiting (pid: 5507)
[2023-07-02 13:56:51 +0700] [5523] [INFO] Booting worker with pid: 5523
[2023-07-02 13:56:52,885] ERROR in app: Exception on /players [GET]
Traceback (most recent call last):
  File "/usr/lib/python3/dist-packages/flask/app.py", line 2070, in wsgi_app
    response = self.full_dispatch_request()
  File "/usr/lib/python3/dist-packages/flask/app.py", line 1515, in full_dispatch_request
    rv = self.handle_user_exception(e)
  File "/usr/lib/python3/dist-packages/flask/app.py", line 1513, in full_dispatch_request
    rv = self.dispatch_request()
  File "/usr/lib/python3/dist-packages/flask/app.py", line 1499, in dispatch_request
    return self.ensure_sync(self.view_functions[rule.endpoint])(**req.view_args)
  File "/home/ultiv/Code/DevC/app.py", line 37, in get_players
    player["ranks"] += " " + player["div"]
KeyError: 'ranks'
[2023-07-02 13:57:10 +0700] [5523] [INFO] Worker reloading: /home/ultiv/Code/DevC/app.py modified
[2023-07-02 13:57:10 +0700] [5523] [INFO] Worker exiting (pid: 5523)
[2023-07-02 13:57:10 +0700] [5539] [INFO] Booting worker with pid: 5539
[2023-07-02 13:57:10,907] ERROR in app: Exception on /players [GET]
Traceback (most recent call last):
  File "/usr/lib/python3/dist-packages/flask/app.py", line 2070, in wsgi_app
    response = self.full_dispatch_request()
  File "/usr/lib/python3/dist-packages/flask/app.py", line 1515, in full_dispatch_request
    rv = self.handle_user_exception(e)
  File "/usr/lib/python3/dist-packages/flask/app.py", line 1513, in full_dispatch_request
    rv = self.dispatch_request()
  File "/usr/lib/python3/dist-packages/flask/app.py", line 1499, in dispatch_request
    return self.ensure_sync(self.view_functions[rule.endpoint])(**req.view_args)
  File "/home/ultiv/Code/DevC/app.py", line 37, in get_players
    player["rank"] += " " + player["div"]
TypeError: can only concatenate str (not "int") to str
[2023-07-02 13:57:40 +0700] [5539] [INFO] Worker reloading: /home/ultiv/Code/DevC/app.py modified
[2023-07-02 13:57:40 +0700] [5539] [INFO] Worker exiting (pid: 5539)
[2023-07-02 13:57:40 +0700] [5556] [INFO] Booting worker with pid: 5556
[2023-07-02 13:58:00 +0700] [5556] [INFO] Worker reloading: /home/ultiv/Code/DevC/app.py modified
[2023-07-02 13:58:00 +0700] [5556] [INFO] Worker exiting (pid: 5556)
[2023-07-02 13:58:01 +0700] [5569] [INFO] Booting worker with pid: 5569
[2023-07-02 13:58:11 +0700] [5569] [INFO] Worker reloading: /home/ultiv/Code/DevC/app.py modified
[2023-07-02 13:58:11 +0700] [5569] [INFO] Worker exiting (pid: 5569)
[2023-07-02 13:58:11 +0700] [5579] [INFO] Booting worker with pid: 5579
[2023-07-02 13:58:26 +0700] [5579] [INFO] Worker reloading: /home/ultiv/Code/DevC/app.py modified
[2023-07-02 13:58:26 +0700] [5579] [INFO] Worker exiting (pid: 5579)
[2023-07-02 13:58:26 +0700] [5592] [INFO] Booting worker with pid: 5592
[2023-07-02 14:00:19 +0700] [5592] [INFO] Worker reloading: /home/ultiv/Code/DevC/app.py modified
[2023-07-02 14:00:19 +0700] [5592] [INFO] Worker exiting (pid: 5592)
[2023-07-02 14:00:20 +0700] [5656] [INFO] Booting worker with pid: 5656
[2023-07-02 14:00:23 +0700] [5656] [ERROR] Error handling request
Traceback (most recent call last):
  File "/usr/lib/python3/dist-packages/gunicorn/workers/sync.py", line 182, in handle_request
    resp.write_file(respiter)
  File "/usr/lib/python3/dist-packages/gunicorn/http/wsgi.py", line 385, in write_file
    if not self.sendfile(respiter):
  File "/usr/lib/python3/dist-packages/gunicorn/http/wsgi.py", line 375, in sendfile
    self.sock.sendfile(respiter.filelike, count=nbytes)
  File "/usr/lib/python3.10/socket.py", line 484, in sendfile
    return self._sendfile_use_sendfile(file, offset, count)
  File "/usr/lib/python3.10/socket.py", line 348, in _sendfile_use_sendfile
    self._check_sendfile_params(file, offset, count)
  File "/usr/lib/python3.10/socket.py", line 462, in _check_sendfile_params
    raise ValueError(
ValueError: count must be a positive integer (got 0)
[2023-07-02 14:03:36 +0700] [5656] [INFO] Worker reloading: /home/ultiv/Code/DevC/lol_metadata.py modified
[2023-07-02 14:03:36 +0700] [5656] [INFO] Worker exiting (pid: 5656)
[2023-07-02 14:03:37 +0700] [5727] [INFO] Booting worker with pid: 5727
[2023-07-02 14:03:43 +0700] [5727] [INFO] Worker reloading: /home/ultiv/Code/DevC/lol_metadata.py modified
[2023-07-02 14:03:43 +0700] [5727] [INFO] Worker exiting (pid: 5727)
[2023-07-02 14:03:43 +0700] [5737] [INFO] Booting worker with pid: 5737
[2023-07-02 14:03:46 +0700] [5737] [INFO] Worker reloading: /home/ultiv/Code/DevC/app.py modified
[2023-07-02 14:03:46 +0700] [5737] [INFO] Worker exiting (pid: 5737)
[2023-07-02 14:03:47 +0700] [5746] [INFO] Booting worker with pid: 5746
[2023-07-02 14:03:52 +0700] [5746] [INFO] Worker reloading: /home/ultiv/Code/DevC/app.py modified
[2023-07-02 14:03:52 +0700] [5746] [INFO] Worker exiting (pid: 5746)
[2023-07-02 14:03:53 +0700] [5755] [INFO] Booting worker with pid: 5755
[2023-07-02 14:04:27,387] ERROR in app: Exception on /teams [GET]
Traceback (most recent call last):
  File "/usr/lib/python3/dist-packages/flask/app.py", line 2070, in wsgi_app
    response = self.full_dispatch_request()
  File "/usr/lib/python3/dist-packages/flask/app.py", line 1515, in full_dispatch_request
    rv = self.handle_user_exception(e)
  File "/usr/lib/python3/dist-packages/flask/app.py", line 1513, in full_dispatch_request
    rv = self.dispatch_request()
  File "/usr/lib/python3/dist-packages/flask/app.py", line 1499, in dispatch_request
    return self.ensure_sync(self.view_functions[rule.endpoint])(**req.view_args)
  File "/home/ultiv/Code/DevC/app.py", line 58, in teams
    teams = balance()
  File "/home/ultiv/Code/DevC/balance.py", line 14, in balance
    players = get_all()
TypeError: get_all() missing 1 required positional argument: 'collection'
[2023-07-02 14:05:25 +0700] [5755] [INFO] Worker reloading: /home/ultiv/Code/DevC/balance.py modified
[2023-07-02 14:05:25 +0700] [5755] [INFO] Worker exiting (pid: 5755)
[2023-07-02 14:05:25 +0700] [5791] [INFO] Booting worker with pid: 5791
[2023-07-02 14:06:04 +0700] [5791] [INFO] Worker reloading: /home/ultiv/Code/DevC/app.py modified
[2023-07-02 14:06:04 +0700] [5791] [INFO] Worker exiting (pid: 5791)
[2023-07-02 14:06:04 +0700] [5804] [INFO] Booting worker with pid: 5804
[2023-07-02 14:09:25 +0700] [5804] [INFO] Worker reloading: /home/ultiv/Code/DevC/app.py modified
[2023-07-02 14:09:25 +0700] [5804] [INFO] Worker exiting (pid: 5804)
[2023-07-02 14:09:25 +0700] [6117] [INFO] Booting worker with pid: 6117
[2023-07-02 14:09:29,440] ERROR in app: Exception on /teams [GET]
Traceback (most recent call last):
  File "/usr/lib/python3/dist-packages/flask/app.py", line 2070, in wsgi_app
    response = self.full_dispatch_request()
  File "/usr/lib/python3/dist-packages/flask/app.py", line 1515, in full_dispatch_request
    rv = self.handle_user_exception(e)
  File "/usr/lib/python3/dist-packages/flask/app.py", line 1513, in full_dispatch_request
    rv = self.dispatch_request()
  File "/usr/lib/python3/dist-packages/flask/app.py", line 1499, in dispatch_request
    return self.ensure_sync(self.view_functions[rule.endpoint])(**req.view_args)
  File "/home/ultiv/Code/DevC/app.py", line 58, in teams
    teams, subs = balance()
  File "/home/ultiv/Code/DevC/balance.py", line 15, in balance
    players.sort(key=lambda p: p["rank"] * 4 + p["div"])
  File "/home/ultiv/Code/DevC/balance.py", line 15, in <lambda>
    players.sort(key=lambda p: p["rank"] * 4 + p["div"])
TypeError: can only concatenate str (not "int") to str
[2023-07-02 14:15:04 +0700] [5365] [INFO] Handling signal: term
[2023-07-02 14:15:04 +0700] [6117] [INFO] Worker exiting (pid: 6117)
[2023-07-02 14:15:04 +0700] [5365] [INFO] Shutting down: Master
[2023-07-02 14:15:04 +0700] [6256] [INFO] Starting gunicorn 20.1.0
[2023-07-02 14:15:04 +0700] [6256] [INFO] Listening at: unix:/run/devc.sock (6256)
[2023-07-02 14:15:04 +0700] [6256] [INFO] Using worker: sync
[2023-07-02 14:15:04 +0700] [6257] [INFO] Booting worker with pid: 6257
[2023-07-02 14:15:53 +0700] [6257] [INFO] Worker reloading: /home/ultiv/Code/DevC/app.py modified
[2023-07-02 14:15:53 +0700] [6257] [INFO] Worker exiting (pid: 6257)
[2023-07-02 14:15:53 +0700] [6286] [INFO] Booting worker with pid: 6286
[2023-07-02 14:19:53,269] ERROR in app: Exception on /teams [GET]
Traceback (most recent call last):
  File "/usr/lib/python3/dist-packages/flask/app.py", line 2070, in wsgi_app
    response = self.full_dispatch_request()
  File "/usr/lib/python3/dist-packages/flask/app.py", line 1515, in full_dispatch_request
    rv = self.handle_user_exception(e)
  File "/usr/lib/python3/dist-packages/flask/app.py", line 1513, in full_dispatch_request
    rv = self.dispatch_request()
  File "/usr/lib/python3/dist-packages/flask/app.py", line 1499, in dispatch_request
    return self.ensure_sync(self.view_functions[rule.endpoint])(**req.view_args)
  File "/home/ultiv/Code/DevC/app.py", line 58, in teams
    teams, subs = balance()
  File "/home/ultiv/Code/DevC/balance.py", line 15, in balance
    players.sort(key=lambda p: p["rank"] * 4 + p["div"])
  File "/home/ultiv/Code/DevC/balance.py", line 15, in <lambda>
    players.sort(key=lambda p: p["rank"] * 4 + p["div"])
TypeError: can only concatenate str (not "int") to str
[2023-07-02 14:22:19 +0700] [6286] [INFO] Worker reloading: /home/ultiv/Code/DevC/balance.py modified
[2023-07-02 14:22:19 +0700] [6286] [INFO] Worker exiting (pid: 6286)
[2023-07-02 14:22:19 +0700] [6383] [INFO] Booting worker with pid: 6383
[2023-07-02 14:22:29,337] ERROR in app: Exception on /teams [GET]
Traceback (most recent call last):
  File "/usr/lib/python3/dist-packages/flask/app.py", line 2070, in wsgi_app
    response = self.full_dispatch_request()
  File "/usr/lib/python3/dist-packages/flask/app.py", line 1515, in full_dispatch_request
    rv = self.handle_user_exception(e)
  File "/usr/lib/python3/dist-packages/flask/app.py", line 1513, in full_dispatch_request
    rv = self.dispatch_request()
  File "/usr/lib/python3/dist-packages/flask/app.py", line 1499, in dispatch_request
    return self.ensure_sync(self.view_functions[rule.endpoint])(**req.view_args)
  File "/home/ultiv/Code/DevC/app.py", line 58, in teams
    teams, subs = balance()
  File "/home/ultiv/Code/DevC/balance.py", line 15, in balance
    players.sort(key=lambda p: ranks.index(p["rank"]) * 4 + p["div"])
  File "/home/ultiv/Code/DevC/balance.py", line 15, in <lambda>
    players.sort(key=lambda p: ranks.index(p["rank"]) * 4 + p["div"])
TypeError: unsupported operand type(s) for +: 'int' and 'str'
[2023-07-02 14:23:35 +0700] [6383] [INFO] Worker reloading: /home/ultiv/Code/DevC/balance.py modified
[2023-07-02 14:23:35 +0700] [6383] [INFO] Worker exiting (pid: 6383)
[2023-07-02 14:23:36 +0700] [6411] [INFO] Booting worker with pid: 6411
[2023-07-02 14:23:37,377] ERROR in app: Exception on /teams [GET]
Traceback (most recent call last):
  File "/usr/lib/python3/dist-packages/flask/app.py", line 2070, in wsgi_app
    response = self.full_dispatch_request()
  File "/usr/lib/python3/dist-packages/flask/app.py", line 1515, in full_dispatch_request
    rv = self.handle_user_exception(e)
  File "/usr/lib/python3/dist-packages/flask/app.py", line 1513, in full_dispatch_request
    rv = self.dispatch_request()
  File "/usr/lib/python3/dist-packages/flask/app.py", line 1499, in dispatch_request
    return self.ensure_sync(self.view_functions[rule.endpoint])(**req.view_args)
  File "/home/ultiv/Code/DevC/app.py", line 58, in teams
    teams, subs = balance()
  File "/home/ultiv/Code/DevC/balance.py", line 19, in balance
    player["pos1"] = positions[player["pos1"]]
TypeError: list indices must be integers or slices, not str
[2023-07-02 14:24:33 +0700] [6411] [INFO] Worker reloading: /home/ultiv/Code/DevC/balance.py modified
[2023-07-02 14:24:33 +0700] [6411] [INFO] Worker exiting (pid: 6411)
[2023-07-02 14:24:33 +0700] [6433] [INFO] Booting worker with pid: 6433
[2023-07-02 14:24:34,127] ERROR in app: Exception on /teams [GET]
Traceback (most recent call last):
  File "/usr/lib/python3/dist-packages/flask/app.py", line 2070, in wsgi_app
    response = self.full_dispatch_request()
  File "/usr/lib/python3/dist-packages/flask/app.py", line 1515, in full_dispatch_request
    rv = self.handle_user_exception(e)
  File "/usr/lib/python3/dist-packages/flask/app.py", line 1513, in full_dispatch_request
    rv = self.dispatch_request()
  File "/usr/lib/python3/dist-packages/flask/app.py", line 1499, in dispatch_request
    return self.ensure_sync(self.view_functions[rule.endpoint])(**req.view_args)
  File "/home/ultiv/Code/DevC/app.py", line 59, in teams
    return render_template("teams.html", teams=teams, items=subs)
  File "/usr/lib/python3/dist-packages/flask/templating.py", line 147, in render_template
    return _render(
  File "/usr/lib/python3/dist-packages/flask/templating.py", line 128, in _render
    rv = template.render(context)
  File "/usr/lib/python3/dist-packages/jinja2/environment.py", line 1291, in render
    self.environment.handle_exception()
  File "/usr/lib/python3/dist-packages/jinja2/environment.py", line 925, in handle_exception
    raise rewrite_traceback_stack(source=source)
  File "/home/ultiv/Code/DevC/templates/teams.html", line 1, in top-level template code
    {% extends 'base.html' %}
  File "/home/ultiv/Code/DevC/templates/base.html", line 21, in top-level template code
    {% block body %}{% endblock %}
  File "/home/ultiv/Code/DevC/templates/teams.html", line 35, in block 'body'
    {% include '_list.html' %}
  File "/home/ultiv/Code/DevC/templates/_list.html", line 4, in top-level template code
    {% for header in labels['headers'] %}
  File "/usr/lib/python3/dist-packages/jinja2/environment.py", line 455, in getitem
    return obj[argument]
jinja2.exceptions.UndefinedError: 'labels' is undefined
[2023-07-02 14:25:41 +0700] [6433] [INFO] Worker reloading: /home/ultiv/Code/DevC/app.py modified
[2023-07-02 14:25:41 +0700] [6433] [INFO] Worker exiting (pid: 6433)
[2023-07-02 14:25:41 +0700] [6470] [INFO] Booting worker with pid: 6470
[2023-07-02 14:28:07 +0700] [6470] [INFO] Worker reloading: /home/ultiv/Code/DevC/balance.py modified
[2023-07-02 14:28:07 +0700] [6470] [INFO] Worker exiting (pid: 6470)
[2023-07-02 14:28:08 +0700] [6526] [INFO] Booting worker with pid: 6526
[2023-07-02 14:28:57 +0700] [6256] [INFO] Handling signal: term
[2023-07-02 14:28:57 +0700] [6526] [INFO] Worker exiting (pid: 6526)
[2023-07-02 14:28:57 +0700] [6256] [INFO] Shutting down: Master
[2023-07-02 14:28:58 +0700] [6551] [INFO] Starting gunicorn 20.1.0
[2023-07-02 14:28:58 +0700] [6551] [INFO] Listening at: unix:/run/devc.sock (6551)
[2023-07-02 14:28:58 +0700] [6551] [INFO] Using worker: sync
[2023-07-02 14:28:58 +0700] [6552] [INFO] Booting worker with pid: 6552
[2023-07-02 14:30:15,999] ERROR in app: Exception on /bracket [GET]
Traceback (most recent call last):
  File "/usr/lib/python3/dist-packages/flask/app.py", line 2070, in wsgi_app
    response = self.full_dispatch_request()
  File "/usr/lib/python3/dist-packages/flask/app.py", line 1516, in full_dispatch_request
    return self.finalize_request(rv)
  File "/usr/lib/python3/dist-packages/flask/app.py", line 1535, in finalize_request
    response = self.make_response(rv)
  File "/usr/lib/python3/dist-packages/flask/app.py", line 1698, in make_response
    raise TypeError(
TypeError: The view function for 'bracket' did not return a valid response. The function either returned None or ended without a return statement.
[2023-07-02 16:33:57 +0700] [6551] [CRITICAL] WORKER TIMEOUT (pid:6552)
[2023-07-02 16:33:57 +0700] [6552] [INFO] Worker exiting (pid: 6552)
[2023-07-02 16:33:57 +0700] [7246] [INFO] Booting worker with pid: 7246
[2023-07-02 17:16:12 +0700] [6551] [INFO] Handling signal: term
[2023-07-02 17:16:12 +0700] [7246] [INFO] Worker exiting (pid: 7246)
[2023-07-02 17:16:13 +0700] [6551] [INFO] Shutting down: Master
